[2025-05-05T18:23:16.027+0300] {taskinstance.py:1979} INFO - Dependencies all met for dep_context=non-requeueable deps ti=<TaskInstance: etl_pipeline.parse_data manual__2025-05-05T13:47:31.178163+00:00 [queued]>
[2025-05-05T18:23:16.031+0300] {taskinstance.py:1979} INFO - Dependencies all met for dep_context=requeueable deps ti=<TaskInstance: etl_pipeline.parse_data manual__2025-05-05T13:47:31.178163+00:00 [queued]>
[2025-05-05T18:23:16.031+0300] {taskinstance.py:2193} INFO - Starting attempt 2 of 2
[2025-05-05T18:23:16.037+0300] {taskinstance.py:2217} INFO - Executing <Task(PythonOperator): parse_data> on 2025-05-05 13:47:31.178163+00:00
[2025-05-05T18:23:16.048+0300] {standard_task_runner.py:60} INFO - Started process 93539 to run task
[2025-05-05T18:23:16.055+0300] {standard_task_runner.py:87} INFO - Running: ['airflow', 'tasks', 'run', 'etl_pipeline', 'parse_data', 'manual__2025-05-05T13:47:31.178163+00:00', '--job-id', '30', '--raw', '--subdir', 'DAGS_FOLDER/etc_pipline.py', '--cfg-path', '/var/folders/rn/6d4yq54d3pz0b5ryq64xt07m0000gn/T/tmpp2ongdt0']
[2025-05-05T18:23:16.056+0300] {standard_task_runner.py:88} INFO - Job 30: Subtask parse_data
[2025-05-05T18:23:16.095+0300] {task_command.py:423} INFO - Running <TaskInstance: etl_pipeline.parse_data manual__2025-05-05T13:47:31.178163+00:00 [running]> on host macbook-air-admin.local
[2025-05-05T18:23:16.124+0300] {taskinstance.py:2513} INFO - Exporting env vars: AIRFLOW_CTX_DAG_OWNER='Bushueva Tatiana' AIRFLOW_CTX_DAG_ID='etl_pipeline' AIRFLOW_CTX_TASK_ID='parse_data' AIRFLOW_CTX_EXECUTION_DATE='2025-05-05T13:47:31.178163+00:00' AIRFLOW_CTX_TRY_NUMBER='2' AIRFLOW_CTX_DAG_RUN_ID='manual__2025-05-05T13:47:31.178163+00:00'
[2025-05-05T18:23:20.430+0300] {taskinstance.py:2731} ERROR - Task failed with exception
Traceback (most recent call last):
  File "/Users/admin/anaconda3/lib/python3.11/site-packages/airflow/models/taskinstance.py", line 444, in _execute_task
    result = _execute_callable(context=context, **execute_callable_kwargs)
             ^^^^^^^^^^^^^^^^^^^^^^^^^^^^^^^^^^^^^^^^^^^^^^^^^^^^^^^^^^^^^
  File "/Users/admin/anaconda3/lib/python3.11/site-packages/airflow/models/taskinstance.py", line 414, in _execute_callable
    return execute_callable(context=context, **execute_callable_kwargs)
           ^^^^^^^^^^^^^^^^^^^^^^^^^^^^^^^^^^^^^^^^^^^^^^^^^^^^^^^^^^^^
  File "/Users/admin/anaconda3/lib/python3.11/site-packages/airflow/operators/python.py", line 200, in execute
    return_value = self.execute_callable()
                   ^^^^^^^^^^^^^^^^^^^^^^^
  File "/Users/admin/anaconda3/lib/python3.11/site-packages/airflow/operators/python.py", line 217, in execute_callable
    return self.python_callable(*self.op_args, **self.op_kwargs)
           ^^^^^^^^^^^^^^^^^^^^^^^^^^^^^^^^^^^^^^^^^^^^^^^^^^^^^
  File "/Users/admin/airflow/dags/etc_pipline.py", line 39, in _parse
    parsed = data_pars('https://www.avito.ru/all/rezume?cd=1&q=%D0%BA%D0%BE%D1%81%D0%BC%D0%B5%D1%82%D0%BE%D0%BB%D0%BE%D0%B3+%D1%80%D0%B5%D0%B7%D1%8E%D0%BC%D0%B5')
             ^^^^^^^^^^^^^^^^^^^^^^^^^^^^^^^^^^^^^^^^^^^^^^^^^^^^^^^^^^^^^^^^^^^^^^^^^^^^^^^^^^^^^^^^^^^^^^^^^^^^^^^^^^^^^^^^^^^^^^^^^^^^^^^^^^^^^^^^^^^^^^^^^^^^^
  File "/Users/admin/airflow/dags/scripts/parse_data.py", line 27, in data_pars
    WebDriverWait(driver, 10).until(EC.presence_of_element_located((By.CLASS_NAME, 'items-items-zOkHg')))
  File "/Users/admin/anaconda3/lib/python3.11/site-packages/selenium/webdriver/support/wait.py", line 96, in until
    value = method(self._driver)
            ^^^^^^^^^^^^^^^^^^^^
  File "/Users/admin/anaconda3/lib/python3.11/site-packages/selenium/webdriver/support/expected_conditions.py", line 84, in _predicate
    return driver.find_element(*locator)
           ^^^^^^^^^^^^^^^^^^^^^^^^^^^^^
  File "/Users/admin/anaconda3/lib/python3.11/site-packages/selenium/webdriver/remote/webdriver.py", line 748, in find_element
    return self.execute(Command.FIND_ELEMENT, {"using": by, "value": value})["value"]
           ^^^^^^^^^^^^^^^^^^^^^^^^^^^^^^^^^^^^^^^^^^^^^^^^^^^^^^^^^^^^^^^^^
  File "/Users/admin/anaconda3/lib/python3.11/site-packages/selenium/webdriver/remote/webdriver.py", line 354, in execute
    self.error_handler.check_response(response)
  File "/Users/admin/anaconda3/lib/python3.11/site-packages/selenium/webdriver/remote/errorhandler.py", line 229, in check_response
    raise exception_class(message, screen, stacktrace)
selenium.common.exceptions.NoSuchWindowException: Message: no such window: target window already closed
from unknown error: web view not found
  (Session info: chrome=135.0.7049.115)
Stacktrace:
0   chromedriver                        0x000000010536ea54 cxxbridge1$str$ptr + 2803960
1   chromedriver                        0x0000000105366cf0 cxxbridge1$str$ptr + 2771860
2   chromedriver                        0x0000000104eb2864 cxxbridge1$string$len + 93028
3   chromedriver                        0x0000000104e8c6e8 chromedriver + 132840
4   chromedriver                        0x0000000104f21404 cxxbridge1$string$len + 546564
5   chromedriver                        0x0000000104f39f8c cxxbridge1$string$len + 647820
6   chromedriver                        0x0000000104eed7ec cxxbridge1$string$len + 334572
7   chromedriver                        0x0000000105333ccc cxxbridge1$str$ptr + 2562928
8   chromedriver                        0x0000000105336f98 cxxbridge1$str$ptr + 2575932
9   chromedriver                        0x00000001053142c4 cxxbridge1$str$ptr + 2433384
10  chromedriver                        0x0000000105337810 cxxbridge1$str$ptr + 2578100
11  chromedriver                        0x00000001053052f0 cxxbridge1$str$ptr + 2371988
12  chromedriver                        0x000000010535757c cxxbridge1$str$ptr + 2708512
13  chromedriver                        0x0000000105357708 cxxbridge1$str$ptr + 2708908
14  chromedriver                        0x000000010536693c cxxbridge1$str$ptr + 2770912
15  libsystem_pthread.dylib             0x000000018b77f034 _pthread_start + 136
16  libsystem_pthread.dylib             0x000000018b779e3c thread_start + 8

[2025-05-05T18:23:20.440+0300] {taskinstance.py:1149} INFO - Marking task as FAILED. dag_id=etl_pipeline, task_id=parse_data, execution_date=20250505T134731, start_date=20250505T152316, end_date=20250505T152320
[2025-05-05T18:23:20.446+0300] {standard_task_runner.py:107} ERROR - Failed to execute job 30 for task parse_data (Message: no such window: target window already closed
from unknown error: web view not found
  (Session info: chrome=135.0.7049.115)
Stacktrace:
0   chromedriver                        0x000000010536ea54 cxxbridge1$str$ptr + 2803960
1   chromedriver                        0x0000000105366cf0 cxxbridge1$str$ptr + 2771860
2   chromedriver                        0x0000000104eb2864 cxxbridge1$string$len + 93028
3   chromedriver                        0x0000000104e8c6e8 chromedriver + 132840
4   chromedriver                        0x0000000104f21404 cxxbridge1$string$len + 546564
5   chromedriver                        0x0000000104f39f8c cxxbridge1$string$len + 647820
6   chromedriver                        0x0000000104eed7ec cxxbridge1$string$len + 334572
7   chromedriver                        0x0000000105333ccc cxxbridge1$str$ptr + 2562928
8   chromedriver                        0x0000000105336f98 cxxbridge1$str$ptr + 2575932
9   chromedriver                        0x00000001053142c4 cxxbridge1$str$ptr + 2433384
10  chromedriver                        0x0000000105337810 cxxbridge1$str$ptr + 2578100
11  chromedriver                        0x00000001053052f0 cxxbridge1$str$ptr + 2371988
12  chromedriver                        0x000000010535757c cxxbridge1$str$ptr + 2708512
13  chromedriver                        0x0000000105357708 cxxbridge1$str$ptr + 2708908
14  chromedriver                        0x000000010536693c cxxbridge1$str$ptr + 2770912
15  libsystem_pthread.dylib             0x000000018b77f034 _pthread_start + 136
16  libsystem_pthread.dylib             0x000000018b779e3c thread_start + 8
; 93539)
[2025-05-05T18:23:20.481+0300] {local_task_job_runner.py:234} INFO - Task exited with return code 1
[2025-05-05T18:23:20.494+0300] {taskinstance.py:3312} INFO - 0 downstream tasks scheduled from follow-on schedule check
