[2025-05-05T12:18:31.127+0300] {taskinstance.py:1979} INFO - Dependencies all met for dep_context=non-requeueable deps ti=<TaskInstance: etl_pipeline.parse_data manual__2025-05-05T09:18:15.951084+00:00 [queued]>
[2025-05-05T12:18:31.139+0300] {taskinstance.py:1979} INFO - Dependencies all met for dep_context=requeueable deps ti=<TaskInstance: etl_pipeline.parse_data manual__2025-05-05T09:18:15.951084+00:00 [queued]>
[2025-05-05T12:18:31.139+0300] {taskinstance.py:2193} INFO - Starting attempt 1 of 2
[2025-05-05T12:18:31.146+0300] {taskinstance.py:2217} INFO - Executing <Task(PythonOperator): parse_data> on 2025-05-05 09:18:15.951084+00:00
[2025-05-05T12:18:31.157+0300] {standard_task_runner.py:60} INFO - Started process 88394 to run task
[2025-05-05T12:18:31.165+0300] {standard_task_runner.py:87} INFO - Running: ['airflow', 'tasks', 'run', 'etl_pipeline', 'parse_data', 'manual__2025-05-05T09:18:15.951084+00:00', '--job-id', '7', '--raw', '--subdir', 'DAGS_FOLDER/etc_pipline.py', '--cfg-path', '/var/folders/rn/6d4yq54d3pz0b5ryq64xt07m0000gn/T/tmpprrrt61i']
[2025-05-05T12:18:31.167+0300] {standard_task_runner.py:88} INFO - Job 7: Subtask parse_data
[2025-05-05T12:18:31.209+0300] {task_command.py:423} INFO - Running <TaskInstance: etl_pipeline.parse_data manual__2025-05-05T09:18:15.951084+00:00 [running]> on host macbook-air-admin.local
[2025-05-05T12:18:31.265+0300] {taskinstance.py:2513} INFO - Exporting env vars: AIRFLOW_CTX_DAG_OWNER='Bushueva Tatiana' AIRFLOW_CTX_DAG_ID='etl_pipeline' AIRFLOW_CTX_TASK_ID='parse_data' AIRFLOW_CTX_EXECUTION_DATE='2025-05-05T09:18:15.951084+00:00' AIRFLOW_CTX_TRY_NUMBER='1' AIRFLOW_CTX_DAG_RUN_ID='manual__2025-05-05T09:18:15.951084+00:00'
[2025-05-05T12:18:31.268+0300] {taskinstance.py:2731} ERROR - Task failed with exception
Traceback (most recent call last):
  File "/Users/admin/anaconda3/lib/python3.11/site-packages/airflow/models/taskinstance.py", line 444, in _execute_task
    result = _execute_callable(context=context, **execute_callable_kwargs)
             ^^^^^^^^^^^^^^^^^^^^^^^^^^^^^^^^^^^^^^^^^^^^^^^^^^^^^^^^^^^^^
  File "/Users/admin/anaconda3/lib/python3.11/site-packages/airflow/models/taskinstance.py", line 414, in _execute_callable
    return execute_callable(context=context, **execute_callable_kwargs)
           ^^^^^^^^^^^^^^^^^^^^^^^^^^^^^^^^^^^^^^^^^^^^^^^^^^^^^^^^^^^^
  File "/Users/admin/anaconda3/lib/python3.11/site-packages/airflow/operators/python.py", line 200, in execute
    return_value = self.execute_callable()
                   ^^^^^^^^^^^^^^^^^^^^^^^
  File "/Users/admin/anaconda3/lib/python3.11/site-packages/airflow/operators/python.py", line 217, in execute_callable
    return self.python_callable(*self.op_args, **self.op_kwargs)
           ^^^^^^^^^^^^^^^^^^^^^^^^^^^^^^^^^^^^^^^^^^^^^^^^^^^^^
  File "/Users/admin/airflow/dags/etc_pipline.py", line 39, in _parse
    parsed = parse_data('https://www.avito.ru/all/rezume?cd=1&p=25&q=%D0%BA%D0%BE%D1%81%D0%BC%D0%B5%D1%82%D0%BE%D0%BB%D0%BE%D0%B3+%D1%80%D0%B5%D0%B7%D1%8E%D0%BC%D0%B5')
             ^^^^^^^^^^^^^^^^^^^^^^^^^^^^^^^^^^^^^^^^^^^^^^^^^^^^^^^^^^^^^^^^^^^^^^^^^^^^^^^^^^^^^^^^^^^^^^^^^^^^^^^^^^^^^^^^^^^^^^^^^^^^^^^^^^^^^^^^^^^^^^^^^^^^^^^^^^^
TypeError: 'module' object is not callable
[2025-05-05T12:18:31.280+0300] {taskinstance.py:1149} INFO - Marking task as UP_FOR_RETRY. dag_id=etl_pipeline, task_id=parse_data, execution_date=20250505T091815, start_date=20250505T091831, end_date=20250505T091831
[2025-05-05T12:18:31.288+0300] {standard_task_runner.py:107} ERROR - Failed to execute job 7 for task parse_data ('module' object is not callable; 88394)
[2025-05-05T12:18:31.312+0300] {local_task_job_runner.py:234} INFO - Task exited with return code 1
[2025-05-05T12:18:31.327+0300] {taskinstance.py:3312} INFO - 0 downstream tasks scheduled from follow-on schedule check
