[2025-05-04T23:46:09.097+0300] {processor.py:161} INFO - Started process (PID=26848) to work on /Users/admin/airflow/dags/scripts/evaluate_model.py
[2025-05-04T23:46:09.098+0300] {processor.py:830} INFO - Processing file /Users/admin/airflow/dags/scripts/evaluate_model.py for tasks to queue
[2025-05-04T23:46:09.098+0300] {logging_mixin.py:188} INFO - [2025-05-04T23:46:09.098+0300] {dagbag.py:540} INFO - Filling up the DagBag from /Users/admin/airflow/dags/scripts/evaluate_model.py
[2025-05-04T23:46:09.100+0300] {logging_mixin.py:188} INFO - [2025-05-04T23:46:09.099+0300] {dagbag.py:350} ERROR - Failed to import: /Users/admin/airflow/dags/scripts/evaluate_model.py
Traceback (most recent call last):
  File "/Users/admin/anaconda3/lib/python3.11/site-packages/airflow/models/dagbag.py", line 346, in parse
    loader.exec_module(new_module)
  File "<frozen importlib._bootstrap_external>", line 936, in exec_module
  File "<frozen importlib._bootstrap_external>", line 1074, in get_code
  File "<frozen importlib._bootstrap_external>", line 1004, in source_to_code
  File "<frozen importlib._bootstrap>", line 241, in _call_with_frames_removed
  File "/Users/admin/airflow/dags/scripts/evaluate_model.py", line 13
    wandb.login '118570a17fac7c4cffe0ad0c784f09cf67222d20'
                ^^^^^^^^^^^^^^^^^^^^^^^^^^^^^^^^^^^^^^^^^^
SyntaxError: invalid syntax
[2025-05-04T23:46:09.101+0300] {processor.py:842} WARNING - No viable dags retrieved from /Users/admin/airflow/dags/scripts/evaluate_model.py
[2025-05-04T23:46:09.150+0300] {processor.py:183} INFO - Processing /Users/admin/airflow/dags/scripts/evaluate_model.py took 0.053 seconds
[2025-05-04T23:47:05.314+0300] {processor.py:161} INFO - Started process (PID=27106) to work on /Users/admin/airflow/dags/scripts/evaluate_model.py
[2025-05-04T23:47:05.315+0300] {processor.py:830} INFO - Processing file /Users/admin/airflow/dags/scripts/evaluate_model.py for tasks to queue
[2025-05-04T23:47:05.315+0300] {logging_mixin.py:188} INFO - [2025-05-04T23:47:05.315+0300] {dagbag.py:540} INFO - Filling up the DagBag from /Users/admin/airflow/dags/scripts/evaluate_model.py
[2025-05-04T23:47:05.317+0300] {logging_mixin.py:188} INFO - [2025-05-04T23:47:05.316+0300] {dagbag.py:350} ERROR - Failed to import: /Users/admin/airflow/dags/scripts/evaluate_model.py
Traceback (most recent call last):
  File "/Users/admin/anaconda3/lib/python3.11/site-packages/airflow/models/dagbag.py", line 346, in parse
    loader.exec_module(new_module)
  File "<frozen importlib._bootstrap_external>", line 936, in exec_module
  File "<frozen importlib._bootstrap_external>", line 1074, in get_code
  File "<frozen importlib._bootstrap_external>", line 1004, in source_to_code
  File "<frozen importlib._bootstrap>", line 241, in _call_with_frames_removed
  File "/Users/admin/airflow/dags/scripts/evaluate_model.py", line 13
    wandb.login '118570a17fac7c4cffe0ad0c784f09cf67222d20'
                ^^^^^^^^^^^^^^^^^^^^^^^^^^^^^^^^^^^^^^^^^^
SyntaxError: invalid syntax
[2025-05-04T23:47:05.318+0300] {processor.py:842} WARNING - No viable dags retrieved from /Users/admin/airflow/dags/scripts/evaluate_model.py
[2025-05-04T23:47:05.366+0300] {processor.py:183} INFO - Processing /Users/admin/airflow/dags/scripts/evaluate_model.py took 0.052 seconds
[2025-05-04T23:48:34.285+0300] {processor.py:161} INFO - Started process (PID=27527) to work on /Users/admin/airflow/dags/scripts/evaluate_model.py
[2025-05-04T23:48:34.286+0300] {processor.py:830} INFO - Processing file /Users/admin/airflow/dags/scripts/evaluate_model.py for tasks to queue
[2025-05-04T23:48:34.287+0300] {logging_mixin.py:188} INFO - [2025-05-04T23:48:34.286+0300] {dagbag.py:540} INFO - Filling up the DagBag from /Users/admin/airflow/dags/scripts/evaluate_model.py
[2025-05-04T23:48:34.293+0300] {logging_mixin.py:188} INFO - [2025-05-04T23:48:34.292+0300] {dagbag.py:350} ERROR - Failed to import: /Users/admin/airflow/dags/scripts/evaluate_model.py
Traceback (most recent call last):
  File "/Users/admin/anaconda3/lib/python3.11/site-packages/airflow/models/dagbag.py", line 346, in parse
    loader.exec_module(new_module)
  File "<frozen importlib._bootstrap_external>", line 940, in exec_module
  File "<frozen importlib._bootstrap>", line 241, in _call_with_frames_removed
  File "/Users/admin/airflow/dags/scripts/evaluate_model.py", line 1, in <module>
    from scripts import preprocessing
  File "/Users/admin/airflow/dags/scripts/preprocessing.py", line 168
    if elem == ['Гражданство — Россия']:
    ^^
IndentationError: expected an indented block after 'for' statement on line 167
[2025-05-04T23:48:34.293+0300] {processor.py:842} WARNING - No viable dags retrieved from /Users/admin/airflow/dags/scripts/evaluate_model.py
[2025-05-04T23:48:34.349+0300] {processor.py:183} INFO - Processing /Users/admin/airflow/dags/scripts/evaluate_model.py took 0.064 seconds
[2025-05-04T23:50:04.205+0300] {processor.py:161} INFO - Started process (PID=27949) to work on /Users/admin/airflow/dags/scripts/evaluate_model.py
[2025-05-04T23:50:04.206+0300] {processor.py:830} INFO - Processing file /Users/admin/airflow/dags/scripts/evaluate_model.py for tasks to queue
[2025-05-04T23:50:04.207+0300] {logging_mixin.py:188} INFO - [2025-05-04T23:50:04.207+0300] {dagbag.py:540} INFO - Filling up the DagBag from /Users/admin/airflow/dags/scripts/evaluate_model.py
[2025-05-04T23:50:04.211+0300] {logging_mixin.py:188} INFO - [2025-05-04T23:50:04.210+0300] {dagbag.py:350} ERROR - Failed to import: /Users/admin/airflow/dags/scripts/evaluate_model.py
Traceback (most recent call last):
  File "/Users/admin/anaconda3/lib/python3.11/site-packages/airflow/models/dagbag.py", line 346, in parse
    loader.exec_module(new_module)
  File "<frozen importlib._bootstrap_external>", line 940, in exec_module
  File "<frozen importlib._bootstrap>", line 241, in _call_with_frames_removed
  File "/Users/admin/airflow/dags/scripts/evaluate_model.py", line 1, in <module>
    from scripts import preprocessing
  File "/Users/admin/airflow/dags/scripts/preprocessing.py", line 168
    if elem == ['Гражданство — Россия']:
    ^^
IndentationError: expected an indented block after 'for' statement on line 167
[2025-05-04T23:50:04.211+0300] {processor.py:842} WARNING - No viable dags retrieved from /Users/admin/airflow/dags/scripts/evaluate_model.py
[2025-05-04T23:50:04.259+0300] {processor.py:183} INFO - Processing /Users/admin/airflow/dags/scripts/evaluate_model.py took 0.054 seconds
[2025-05-04T23:51:47.758+0300] {processor.py:161} INFO - Started process (PID=28431) to work on /Users/admin/airflow/dags/scripts/evaluate_model.py
[2025-05-04T23:51:47.760+0300] {processor.py:830} INFO - Processing file /Users/admin/airflow/dags/scripts/evaluate_model.py for tasks to queue
[2025-05-04T23:51:47.761+0300] {logging_mixin.py:188} INFO - [2025-05-04T23:51:47.761+0300] {dagbag.py:540} INFO - Filling up the DagBag from /Users/admin/airflow/dags/scripts/evaluate_model.py
[2025-05-04T23:51:48.068+0300] {logging_mixin.py:188} INFO - [2025-05-04T23:51:48.067+0300] {utils.py:160} INFO - NumExpr defaulting to 8 threads.
[2025-05-04T23:51:51.432+0300] {logging_mixin.py:188} INFO - [2025-05-04T23:51:51.426+0300] {dagbag.py:350} ERROR - Failed to import: /Users/admin/airflow/dags/scripts/evaluate_model.py
Traceback (most recent call last):
  File "/Users/admin/anaconda3/lib/python3.11/site-packages/transformers/utils/import_utils.py", line 1863, in _get_module
    return importlib.import_module("." + module_name, self.__name__)
           ^^^^^^^^^^^^^^^^^^^^^^^^^^^^^^^^^^^^^^^^^^^^^^^^^^^^^^^^^
  File "/Users/admin/anaconda3/lib/python3.11/importlib/__init__.py", line 126, in import_module
    return _bootstrap._gcd_import(name[level:], package, level)
           ^^^^^^^^^^^^^^^^^^^^^^^^^^^^^^^^^^^^^^^^^^^^^^^^^^^^
  File "<frozen importlib._bootstrap>", line 1204, in _gcd_import
  File "<frozen importlib._bootstrap>", line 1176, in _find_and_load
  File "<frozen importlib._bootstrap>", line 1126, in _find_and_load_unlocked
  File "<frozen importlib._bootstrap>", line 241, in _call_with_frames_removed
  File "<frozen importlib._bootstrap>", line 1204, in _gcd_import
  File "<frozen importlib._bootstrap>", line 1176, in _find_and_load
  File "<frozen importlib._bootstrap>", line 1147, in _find_and_load_unlocked
  File "<frozen importlib._bootstrap>", line 690, in _load_unlocked
  File "<frozen importlib._bootstrap_external>", line 940, in exec_module
  File "<frozen importlib._bootstrap>", line 241, in _call_with_frames_removed
  File "/Users/admin/anaconda3/lib/python3.11/site-packages/transformers/data/__init__.py", line 29, in <module>
    from .processors import (
  File "/Users/admin/anaconda3/lib/python3.11/site-packages/transformers/data/processors/__init__.py", line 15, in <module>
    from .glue import glue_convert_examples_to_features, glue_output_modes, glue_processors, glue_tasks_num_labels
  File "/Users/admin/anaconda3/lib/python3.11/site-packages/transformers/data/processors/glue.py", line 79, in <module>
    examples: tf.data.Dataset,
              ^^^^^^^
AttributeError: module 'tensorflow' has no attribute 'data'

The above exception was the direct cause of the following exception:

Traceback (most recent call last):
  File "/Users/admin/anaconda3/lib/python3.11/site-packages/transformers/utils/import_utils.py", line 1863, in _get_module
    return importlib.import_module("." + module_name, self.__name__)
           ^^^^^^^^^^^^^^^^^^^^^^^^^^^^^^^^^^^^^^^^^^^^^^^^^^^^^^^^^
  File "/Users/admin/anaconda3/lib/python3.11/importlib/__init__.py", line 126, in import_module
    return _bootstrap._gcd_import(name[level:], package, level)
           ^^^^^^^^^^^^^^^^^^^^^^^^^^^^^^^^^^^^^^^^^^^^^^^^^^^^
  File "<frozen importlib._bootstrap>", line 1204, in _gcd_import
  File "<frozen importlib._bootstrap>", line 1176, in _find_and_load
  File "<frozen importlib._bootstrap>", line 1147, in _find_and_load_unlocked
  File "<frozen importlib._bootstrap>", line 690, in _load_unlocked
  File "<frozen importlib._bootstrap_external>", line 940, in exec_module
  File "<frozen importlib._bootstrap>", line 241, in _call_with_frames_removed
  File "/Users/admin/anaconda3/lib/python3.11/site-packages/transformers/modeling_tf_utils.py", line 37, in <module>
    from . import DataCollatorWithPadding, DefaultDataCollator
  File "<frozen importlib._bootstrap>", line 1229, in _handle_fromlist
  File "/Users/admin/anaconda3/lib/python3.11/site-packages/transformers/utils/import_utils.py", line 1851, in __getattr__
    module = self._get_module(self._class_to_module[name])
             ^^^^^^^^^^^^^^^^^^^^^^^^^^^^^^^^^^^^^^^^^^^^^
  File "/Users/admin/anaconda3/lib/python3.11/site-packages/transformers/utils/import_utils.py", line 1865, in _get_module
    raise RuntimeError(
RuntimeError: Failed to import transformers.data.data_collator because of the following error (look up to see its traceback):
module 'tensorflow' has no attribute 'data'

The above exception was the direct cause of the following exception:

Traceback (most recent call last):
  File "/Users/admin/anaconda3/lib/python3.11/site-packages/transformers/utils/import_utils.py", line 1863, in _get_module
    return importlib.import_module("." + module_name, self.__name__)
           ^^^^^^^^^^^^^^^^^^^^^^^^^^^^^^^^^^^^^^^^^^^^^^^^^^^^^^^^^
  File "/Users/admin/anaconda3/lib/python3.11/importlib/__init__.py", line 126, in import_module
    return _bootstrap._gcd_import(name[level:], package, level)
           ^^^^^^^^^^^^^^^^^^^^^^^^^^^^^^^^^^^^^^^^^^^^^^^^^^^^
  File "<frozen importlib._bootstrap>", line 1204, in _gcd_import
  File "<frozen importlib._bootstrap>", line 1176, in _find_and_load
  File "<frozen importlib._bootstrap>", line 1147, in _find_and_load_unlocked
  File "<frozen importlib._bootstrap>", line 690, in _load_unlocked
  File "<frozen importlib._bootstrap_external>", line 940, in exec_module
  File "<frozen importlib._bootstrap>", line 241, in _call_with_frames_removed
  File "/Users/admin/anaconda3/lib/python3.11/site-packages/transformers/integrations/integration_utils.py", line 36, in <module>
    from .. import PreTrainedModel, TFPreTrainedModel
  File "<frozen importlib._bootstrap>", line 1229, in _handle_fromlist
  File "/Users/admin/anaconda3/lib/python3.11/site-packages/transformers/utils/import_utils.py", line 1851, in __getattr__
    module = self._get_module(self._class_to_module[name])
             ^^^^^^^^^^^^^^^^^^^^^^^^^^^^^^^^^^^^^^^^^^^^^
  File "/Users/admin/anaconda3/lib/python3.11/site-packages/transformers/utils/import_utils.py", line 1865, in _get_module
    raise RuntimeError(
RuntimeError: Failed to import transformers.modeling_tf_utils because of the following error (look up to see its traceback):
Failed to import transformers.data.data_collator because of the following error (look up to see its traceback):
module 'tensorflow' has no attribute 'data'

The above exception was the direct cause of the following exception:

Traceback (most recent call last):
  File "/Users/admin/anaconda3/lib/python3.11/site-packages/airflow/models/dagbag.py", line 346, in parse
    loader.exec_module(new_module)
  File "<frozen importlib._bootstrap_external>", line 940, in exec_module
  File "<frozen importlib._bootstrap>", line 241, in _call_with_frames_removed
  File "/Users/admin/airflow/dags/scripts/evaluate_model.py", line 2, in <module>
    from sentence_transformers import SentenceTransformer
  File "/Users/admin/anaconda3/lib/python3.11/site-packages/sentence_transformers/__init__.py", line 14, in <module>
    from sentence_transformers.cross_encoder.CrossEncoder import CrossEncoder
  File "/Users/admin/anaconda3/lib/python3.11/site-packages/sentence_transformers/cross_encoder/__init__.py", line 3, in <module>
    from .CrossEncoder import CrossEncoder
  File "/Users/admin/anaconda3/lib/python3.11/site-packages/sentence_transformers/cross_encoder/CrossEncoder.py", line 18, in <module>
    from sentence_transformers.evaluation.SentenceEvaluator import SentenceEvaluator
  File "/Users/admin/anaconda3/lib/python3.11/site-packages/sentence_transformers/evaluation/__init__.py", line 9, in <module>
    from .NanoBEIREvaluator import NanoBEIREvaluator
  File "/Users/admin/anaconda3/lib/python3.11/site-packages/sentence_transformers/evaluation/NanoBEIREvaluator.py", line 11, in <module>
    from sentence_transformers import SentenceTransformer
  File "/Users/admin/anaconda3/lib/python3.11/site-packages/sentence_transformers/SentenceTransformer.py", line 33, in <module>
    from sentence_transformers.model_card import SentenceTransformerModelCardData, generate_model_card
  File "/Users/admin/anaconda3/lib/python3.11/site-packages/sentence_transformers/model_card.py", line 25, in <module>
    from transformers.integrations import CodeCarbonCallback
  File "<frozen importlib._bootstrap>", line 1229, in _handle_fromlist
  File "/Users/admin/anaconda3/lib/python3.11/site-packages/transformers/utils/import_utils.py", line 1851, in __getattr__
    module = self._get_module(self._class_to_module[name])
             ^^^^^^^^^^^^^^^^^^^^^^^^^^^^^^^^^^^^^^^^^^^^^
  File "/Users/admin/anaconda3/lib/python3.11/site-packages/transformers/utils/import_utils.py", line 1865, in _get_module
    raise RuntimeError(
RuntimeError: Failed to import transformers.integrations.integration_utils because of the following error (look up to see its traceback):
Failed to import transformers.modeling_tf_utils because of the following error (look up to see its traceback):
Failed to import transformers.data.data_collator because of the following error (look up to see its traceback):
module 'tensorflow' has no attribute 'data'
[2025-05-04T23:51:51.434+0300] {processor.py:842} WARNING - No viable dags retrieved from /Users/admin/airflow/dags/scripts/evaluate_model.py
[2025-05-04T23:51:51.487+0300] {processor.py:183} INFO - Processing /Users/admin/airflow/dags/scripts/evaluate_model.py took 3.730 seconds
[2025-05-04T23:53:20.167+0300] {processor.py:161} INFO - Started process (PID=28867) to work on /Users/admin/airflow/dags/scripts/evaluate_model.py
[2025-05-04T23:53:20.168+0300] {processor.py:830} INFO - Processing file /Users/admin/airflow/dags/scripts/evaluate_model.py for tasks to queue
[2025-05-04T23:53:20.169+0300] {logging_mixin.py:188} INFO - [2025-05-04T23:53:20.168+0300] {dagbag.py:540} INFO - Filling up the DagBag from /Users/admin/airflow/dags/scripts/evaluate_model.py
[2025-05-04T23:53:20.365+0300] {logging_mixin.py:188} INFO - [2025-05-04T23:53:20.365+0300] {utils.py:160} INFO - NumExpr defaulting to 8 threads.
[2025-05-04T23:53:23.223+0300] {logging_mixin.py:188} INFO - [2025-05-04T23:53:23.219+0300] {dagbag.py:350} ERROR - Failed to import: /Users/admin/airflow/dags/scripts/evaluate_model.py
Traceback (most recent call last):
  File "/Users/admin/anaconda3/lib/python3.11/site-packages/transformers/utils/import_utils.py", line 1863, in _get_module
    return importlib.import_module("." + module_name, self.__name__)
           ^^^^^^^^^^^^^^^^^^^^^^^^^^^^^^^^^^^^^^^^^^^^^^^^^^^^^^^^^
  File "/Users/admin/anaconda3/lib/python3.11/importlib/__init__.py", line 126, in import_module
    return _bootstrap._gcd_import(name[level:], package, level)
           ^^^^^^^^^^^^^^^^^^^^^^^^^^^^^^^^^^^^^^^^^^^^^^^^^^^^
  File "<frozen importlib._bootstrap>", line 1204, in _gcd_import
  File "<frozen importlib._bootstrap>", line 1176, in _find_and_load
  File "<frozen importlib._bootstrap>", line 1126, in _find_and_load_unlocked
  File "<frozen importlib._bootstrap>", line 241, in _call_with_frames_removed
  File "<frozen importlib._bootstrap>", line 1204, in _gcd_import
  File "<frozen importlib._bootstrap>", line 1176, in _find_and_load
  File "<frozen importlib._bootstrap>", line 1147, in _find_and_load_unlocked
  File "<frozen importlib._bootstrap>", line 690, in _load_unlocked
  File "<frozen importlib._bootstrap_external>", line 940, in exec_module
  File "<frozen importlib._bootstrap>", line 241, in _call_with_frames_removed
  File "/Users/admin/anaconda3/lib/python3.11/site-packages/transformers/data/__init__.py", line 29, in <module>
    from .processors import (
  File "/Users/admin/anaconda3/lib/python3.11/site-packages/transformers/data/processors/__init__.py", line 15, in <module>
    from .glue import glue_convert_examples_to_features, glue_output_modes, glue_processors, glue_tasks_num_labels
  File "/Users/admin/anaconda3/lib/python3.11/site-packages/transformers/data/processors/glue.py", line 79, in <module>
    examples: tf.data.Dataset,
              ^^^^^^^
AttributeError: module 'tensorflow' has no attribute 'data'

The above exception was the direct cause of the following exception:

Traceback (most recent call last):
  File "/Users/admin/anaconda3/lib/python3.11/site-packages/transformers/utils/import_utils.py", line 1863, in _get_module
    return importlib.import_module("." + module_name, self.__name__)
           ^^^^^^^^^^^^^^^^^^^^^^^^^^^^^^^^^^^^^^^^^^^^^^^^^^^^^^^^^
  File "/Users/admin/anaconda3/lib/python3.11/importlib/__init__.py", line 126, in import_module
    return _bootstrap._gcd_import(name[level:], package, level)
           ^^^^^^^^^^^^^^^^^^^^^^^^^^^^^^^^^^^^^^^^^^^^^^^^^^^^
  File "<frozen importlib._bootstrap>", line 1204, in _gcd_import
  File "<frozen importlib._bootstrap>", line 1176, in _find_and_load
  File "<frozen importlib._bootstrap>", line 1147, in _find_and_load_unlocked
  File "<frozen importlib._bootstrap>", line 690, in _load_unlocked
  File "<frozen importlib._bootstrap_external>", line 940, in exec_module
  File "<frozen importlib._bootstrap>", line 241, in _call_with_frames_removed
  File "/Users/admin/anaconda3/lib/python3.11/site-packages/transformers/modeling_tf_utils.py", line 37, in <module>
    from . import DataCollatorWithPadding, DefaultDataCollator
  File "<frozen importlib._bootstrap>", line 1229, in _handle_fromlist
  File "/Users/admin/anaconda3/lib/python3.11/site-packages/transformers/utils/import_utils.py", line 1851, in __getattr__
    module = self._get_module(self._class_to_module[name])
             ^^^^^^^^^^^^^^^^^^^^^^^^^^^^^^^^^^^^^^^^^^^^^
  File "/Users/admin/anaconda3/lib/python3.11/site-packages/transformers/utils/import_utils.py", line 1865, in _get_module
    raise RuntimeError(
RuntimeError: Failed to import transformers.data.data_collator because of the following error (look up to see its traceback):
module 'tensorflow' has no attribute 'data'

The above exception was the direct cause of the following exception:

Traceback (most recent call last):
  File "/Users/admin/anaconda3/lib/python3.11/site-packages/transformers/utils/import_utils.py", line 1863, in _get_module
    return importlib.import_module("." + module_name, self.__name__)
           ^^^^^^^^^^^^^^^^^^^^^^^^^^^^^^^^^^^^^^^^^^^^^^^^^^^^^^^^^
  File "/Users/admin/anaconda3/lib/python3.11/importlib/__init__.py", line 126, in import_module
    return _bootstrap._gcd_import(name[level:], package, level)
           ^^^^^^^^^^^^^^^^^^^^^^^^^^^^^^^^^^^^^^^^^^^^^^^^^^^^
  File "<frozen importlib._bootstrap>", line 1204, in _gcd_import
  File "<frozen importlib._bootstrap>", line 1176, in _find_and_load
  File "<frozen importlib._bootstrap>", line 1147, in _find_and_load_unlocked
  File "<frozen importlib._bootstrap>", line 690, in _load_unlocked
  File "<frozen importlib._bootstrap_external>", line 940, in exec_module
  File "<frozen importlib._bootstrap>", line 241, in _call_with_frames_removed
  File "/Users/admin/anaconda3/lib/python3.11/site-packages/transformers/integrations/integration_utils.py", line 36, in <module>
    from .. import PreTrainedModel, TFPreTrainedModel
  File "<frozen importlib._bootstrap>", line 1229, in _handle_fromlist
  File "/Users/admin/anaconda3/lib/python3.11/site-packages/transformers/utils/import_utils.py", line 1851, in __getattr__
    module = self._get_module(self._class_to_module[name])
             ^^^^^^^^^^^^^^^^^^^^^^^^^^^^^^^^^^^^^^^^^^^^^
  File "/Users/admin/anaconda3/lib/python3.11/site-packages/transformers/utils/import_utils.py", line 1865, in _get_module
    raise RuntimeError(
RuntimeError: Failed to import transformers.modeling_tf_utils because of the following error (look up to see its traceback):
Failed to import transformers.data.data_collator because of the following error (look up to see its traceback):
module 'tensorflow' has no attribute 'data'

The above exception was the direct cause of the following exception:

Traceback (most recent call last):
  File "/Users/admin/anaconda3/lib/python3.11/site-packages/airflow/models/dagbag.py", line 346, in parse
    loader.exec_module(new_module)
  File "<frozen importlib._bootstrap_external>", line 940, in exec_module
  File "<frozen importlib._bootstrap>", line 241, in _call_with_frames_removed
  File "/Users/admin/airflow/dags/scripts/evaluate_model.py", line 2, in <module>
    from sentence_transformers import SentenceTransformer
  File "/Users/admin/anaconda3/lib/python3.11/site-packages/sentence_transformers/__init__.py", line 14, in <module>
    from sentence_transformers.cross_encoder.CrossEncoder import CrossEncoder
  File "/Users/admin/anaconda3/lib/python3.11/site-packages/sentence_transformers/cross_encoder/__init__.py", line 3, in <module>
    from .CrossEncoder import CrossEncoder
  File "/Users/admin/anaconda3/lib/python3.11/site-packages/sentence_transformers/cross_encoder/CrossEncoder.py", line 18, in <module>
    from sentence_transformers.evaluation.SentenceEvaluator import SentenceEvaluator
  File "/Users/admin/anaconda3/lib/python3.11/site-packages/sentence_transformers/evaluation/__init__.py", line 9, in <module>
    from .NanoBEIREvaluator import NanoBEIREvaluator
  File "/Users/admin/anaconda3/lib/python3.11/site-packages/sentence_transformers/evaluation/NanoBEIREvaluator.py", line 11, in <module>
    from sentence_transformers import SentenceTransformer
  File "/Users/admin/anaconda3/lib/python3.11/site-packages/sentence_transformers/SentenceTransformer.py", line 33, in <module>
    from sentence_transformers.model_card import SentenceTransformerModelCardData, generate_model_card
  File "/Users/admin/anaconda3/lib/python3.11/site-packages/sentence_transformers/model_card.py", line 25, in <module>
    from transformers.integrations import CodeCarbonCallback
  File "<frozen importlib._bootstrap>", line 1229, in _handle_fromlist
  File "/Users/admin/anaconda3/lib/python3.11/site-packages/transformers/utils/import_utils.py", line 1851, in __getattr__
    module = self._get_module(self._class_to_module[name])
             ^^^^^^^^^^^^^^^^^^^^^^^^^^^^^^^^^^^^^^^^^^^^^
  File "/Users/admin/anaconda3/lib/python3.11/site-packages/transformers/utils/import_utils.py", line 1865, in _get_module
    raise RuntimeError(
RuntimeError: Failed to import transformers.integrations.integration_utils because of the following error (look up to see its traceback):
Failed to import transformers.modeling_tf_utils because of the following error (look up to see its traceback):
Failed to import transformers.data.data_collator because of the following error (look up to see its traceback):
module 'tensorflow' has no attribute 'data'
[2025-05-04T23:53:23.225+0300] {processor.py:842} WARNING - No viable dags retrieved from /Users/admin/airflow/dags/scripts/evaluate_model.py
[2025-05-04T23:53:23.275+0300] {processor.py:183} INFO - Processing /Users/admin/airflow/dags/scripts/evaluate_model.py took 3.109 seconds
[2025-05-04T23:59:17.874+0300] {processor.py:161} INFO - Started process (PID=29336) to work on /Users/admin/airflow/dags/scripts/evaluate_model.py
[2025-05-04T23:59:17.875+0300] {processor.py:830} INFO - Processing file /Users/admin/airflow/dags/scripts/evaluate_model.py for tasks to queue
[2025-05-04T23:59:17.876+0300] {logging_mixin.py:188} INFO - [2025-05-04T23:59:17.876+0300] {dagbag.py:540} INFO - Filling up the DagBag from /Users/admin/airflow/dags/scripts/evaluate_model.py
[2025-05-04T23:59:18.071+0300] {logging_mixin.py:188} INFO - [2025-05-04T23:59:18.071+0300] {utils.py:160} INFO - NumExpr defaulting to 8 threads.
[2025-05-05T01:59:21.121+0300] {logging_mixin.py:188} INFO - [2025-05-05T01:59:21.115+0300] {dagbag.py:350} ERROR - Failed to import: /Users/admin/airflow/dags/scripts/evaluate_model.py
Traceback (most recent call last):
  File "/Users/admin/anaconda3/lib/python3.11/site-packages/transformers/utils/import_utils.py", line 1863, in _get_module
    return importlib.import_module("." + module_name, self.__name__)
           ^^^^^^^^^^^^^^^^^^^^^^^^^^^^^^^^^^^^^^^^^^^^^^^^^^^^^^^^^
  File "/Users/admin/anaconda3/lib/python3.11/importlib/__init__.py", line 126, in import_module
    return _bootstrap._gcd_import(name[level:], package, level)
           ^^^^^^^^^^^^^^^^^^^^^^^^^^^^^^^^^^^^^^^^^^^^^^^^^^^^
  File "<frozen importlib._bootstrap>", line 1204, in _gcd_import
  File "<frozen importlib._bootstrap>", line 1176, in _find_and_load
  File "<frozen importlib._bootstrap>", line 1126, in _find_and_load_unlocked
  File "<frozen importlib._bootstrap>", line 241, in _call_with_frames_removed
  File "<frozen importlib._bootstrap>", line 1204, in _gcd_import
  File "<frozen importlib._bootstrap>", line 1176, in _find_and_load
  File "<frozen importlib._bootstrap>", line 1147, in _find_and_load_unlocked
  File "<frozen importlib._bootstrap>", line 690, in _load_unlocked
  File "<frozen importlib._bootstrap_external>", line 940, in exec_module
  File "<frozen importlib._bootstrap>", line 241, in _call_with_frames_removed
  File "/Users/admin/anaconda3/lib/python3.11/site-packages/transformers/data/__init__.py", line 29, in <module>
    from .processors import (
  File "/Users/admin/anaconda3/lib/python3.11/site-packages/transformers/data/processors/__init__.py", line 15, in <module>
    from .glue import glue_convert_examples_to_features, glue_output_modes, glue_processors, glue_tasks_num_labels
  File "/Users/admin/anaconda3/lib/python3.11/site-packages/transformers/data/processors/glue.py", line 79, in <module>
    examples: tf.data.Dataset,
              ^^^^^^^
AttributeError: module 'tensorflow' has no attribute 'data'

The above exception was the direct cause of the following exception:

Traceback (most recent call last):
  File "/Users/admin/anaconda3/lib/python3.11/site-packages/transformers/utils/import_utils.py", line 1863, in _get_module
    return importlib.import_module("." + module_name, self.__name__)
           ^^^^^^^^^^^^^^^^^^^^^^^^^^^^^^^^^^^^^^^^^^^^^^^^^^^^^^^^^
  File "/Users/admin/anaconda3/lib/python3.11/importlib/__init__.py", line 126, in import_module
    return _bootstrap._gcd_import(name[level:], package, level)
           ^^^^^^^^^^^^^^^^^^^^^^^^^^^^^^^^^^^^^^^^^^^^^^^^^^^^
  File "<frozen importlib._bootstrap>", line 1204, in _gcd_import
  File "<frozen importlib._bootstrap>", line 1176, in _find_and_load
  File "<frozen importlib._bootstrap>", line 1147, in _find_and_load_unlocked
  File "<frozen importlib._bootstrap>", line 690, in _load_unlocked
  File "<frozen importlib._bootstrap_external>", line 940, in exec_module
  File "<frozen importlib._bootstrap>", line 241, in _call_with_frames_removed
  File "/Users/admin/anaconda3/lib/python3.11/site-packages/transformers/modeling_tf_utils.py", line 37, in <module>
    from . import DataCollatorWithPadding, DefaultDataCollator
  File "<frozen importlib._bootstrap>", line 1229, in _handle_fromlist
  File "/Users/admin/anaconda3/lib/python3.11/site-packages/transformers/utils/import_utils.py", line 1851, in __getattr__
    module = self._get_module(self._class_to_module[name])
             ^^^^^^^^^^^^^^^^^^^^^^^^^^^^^^^^^^^^^^^^^^^^^
  File "/Users/admin/anaconda3/lib/python3.11/site-packages/transformers/utils/import_utils.py", line 1865, in _get_module
    raise RuntimeError(
RuntimeError: Failed to import transformers.data.data_collator because of the following error (look up to see its traceback):
module 'tensorflow' has no attribute 'data'

The above exception was the direct cause of the following exception:

Traceback (most recent call last):
  File "/Users/admin/anaconda3/lib/python3.11/site-packages/transformers/utils/import_utils.py", line 1863, in _get_module
    return importlib.import_module("." + module_name, self.__name__)
           ^^^^^^^^^^^^^^^^^^^^^^^^^^^^^^^^^^^^^^^^^^^^^^^^^^^^^^^^^
  File "/Users/admin/anaconda3/lib/python3.11/importlib/__init__.py", line 126, in import_module
    return _bootstrap._gcd_import(name[level:], package, level)
           ^^^^^^^^^^^^^^^^^^^^^^^^^^^^^^^^^^^^^^^^^^^^^^^^^^^^
  File "<frozen importlib._bootstrap>", line 1204, in _gcd_import
  File "<frozen importlib._bootstrap>", line 1176, in _find_and_load
  File "<frozen importlib._bootstrap>", line 1147, in _find_and_load_unlocked
  File "<frozen importlib._bootstrap>", line 690, in _load_unlocked
  File "<frozen importlib._bootstrap_external>", line 940, in exec_module
  File "<frozen importlib._bootstrap>", line 241, in _call_with_frames_removed
  File "/Users/admin/anaconda3/lib/python3.11/site-packages/transformers/integrations/integration_utils.py", line 36, in <module>
    from .. import PreTrainedModel, TFPreTrainedModel
  File "<frozen importlib._bootstrap>", line 1229, in _handle_fromlist
  File "/Users/admin/anaconda3/lib/python3.11/site-packages/transformers/utils/import_utils.py", line 1851, in __getattr__
    module = self._get_module(self._class_to_module[name])
             ^^^^^^^^^^^^^^^^^^^^^^^^^^^^^^^^^^^^^^^^^^^^^
  File "/Users/admin/anaconda3/lib/python3.11/site-packages/transformers/utils/import_utils.py", line 1865, in _get_module
    raise RuntimeError(
RuntimeError: Failed to import transformers.modeling_tf_utils because of the following error (look up to see its traceback):
Failed to import transformers.data.data_collator because of the following error (look up to see its traceback):
module 'tensorflow' has no attribute 'data'

The above exception was the direct cause of the following exception:

Traceback (most recent call last):
  File "/Users/admin/anaconda3/lib/python3.11/site-packages/airflow/models/dagbag.py", line 346, in parse
    loader.exec_module(new_module)
  File "<frozen importlib._bootstrap_external>", line 940, in exec_module
  File "<frozen importlib._bootstrap>", line 241, in _call_with_frames_removed
  File "/Users/admin/airflow/dags/scripts/evaluate_model.py", line 2, in <module>
    from sentence_transformers import SentenceTransformer
  File "/Users/admin/anaconda3/lib/python3.11/site-packages/sentence_transformers/__init__.py", line 14, in <module>
    from sentence_transformers.cross_encoder.CrossEncoder import CrossEncoder
  File "/Users/admin/anaconda3/lib/python3.11/site-packages/sentence_transformers/cross_encoder/__init__.py", line 3, in <module>
    from .CrossEncoder import CrossEncoder
  File "/Users/admin/anaconda3/lib/python3.11/site-packages/sentence_transformers/cross_encoder/CrossEncoder.py", line 18, in <module>
    from sentence_transformers.evaluation.SentenceEvaluator import SentenceEvaluator
  File "/Users/admin/anaconda3/lib/python3.11/site-packages/sentence_transformers/evaluation/__init__.py", line 9, in <module>
    from .NanoBEIREvaluator import NanoBEIREvaluator
  File "/Users/admin/anaconda3/lib/python3.11/site-packages/sentence_transformers/evaluation/NanoBEIREvaluator.py", line 11, in <module>
    from sentence_transformers import SentenceTransformer
  File "/Users/admin/anaconda3/lib/python3.11/site-packages/sentence_transformers/SentenceTransformer.py", line 33, in <module>
    from sentence_transformers.model_card import SentenceTransformerModelCardData, generate_model_card
  File "/Users/admin/anaconda3/lib/python3.11/site-packages/sentence_transformers/model_card.py", line 25, in <module>
    from transformers.integrations import CodeCarbonCallback
  File "<frozen importlib._bootstrap>", line 1229, in _handle_fromlist
  File "/Users/admin/anaconda3/lib/python3.11/site-packages/transformers/utils/import_utils.py", line 1851, in __getattr__
    module = self._get_module(self._class_to_module[name])
             ^^^^^^^^^^^^^^^^^^^^^^^^^^^^^^^^^^^^^^^^^^^^^
  File "/Users/admin/anaconda3/lib/python3.11/site-packages/transformers/utils/import_utils.py", line 1865, in _get_module
    raise RuntimeError(
RuntimeError: Failed to import transformers.integrations.integration_utils because of the following error (look up to see its traceback):
Failed to import transformers.modeling_tf_utils because of the following error (look up to see its traceback):
Failed to import transformers.data.data_collator because of the following error (look up to see its traceback):
module 'tensorflow' has no attribute 'data'
[2025-05-05T01:59:21.123+0300] {processor.py:842} WARNING - No viable dags retrieved from /Users/admin/airflow/dags/scripts/evaluate_model.py
[2025-05-05T01:59:21.172+0300] {processor.py:183} INFO - Processing /Users/admin/airflow/dags/scripts/evaluate_model.py took 4.143 seconds
