[2025-05-05T17:31:20.531+0300] {taskinstance.py:1979} INFO - Dependencies all met for dep_context=non-requeueable deps ti=<TaskInstance: etl_pipeline.parse_data manual__2025-05-05T13:47:29.321134+00:00 [queued]>
[2025-05-05T17:31:20.534+0300] {taskinstance.py:1979} INFO - Dependencies all met for dep_context=requeueable deps ti=<TaskInstance: etl_pipeline.parse_data manual__2025-05-05T13:47:29.321134+00:00 [queued]>
[2025-05-05T17:31:20.534+0300] {taskinstance.py:2193} INFO - Starting attempt 1 of 2
[2025-05-05T17:31:20.540+0300] {taskinstance.py:2217} INFO - Executing <Task(PythonOperator): parse_data> on 2025-05-05 13:47:29.321134+00:00
[2025-05-05T17:31:20.551+0300] {standard_task_runner.py:60} INFO - Started process 79187 to run task
[2025-05-05T17:31:20.561+0300] {standard_task_runner.py:87} INFO - Running: ['airflow', 'tasks', 'run', 'etl_pipeline', 'parse_data', 'manual__2025-05-05T13:47:29.321134+00:00', '--job-id', '25', '--raw', '--subdir', 'DAGS_FOLDER/etc_pipline.py', '--cfg-path', '/var/folders/rn/6d4yq54d3pz0b5ryq64xt07m0000gn/T/tmp3nkdn6f4']
[2025-05-05T17:31:20.563+0300] {standard_task_runner.py:88} INFO - Job 25: Subtask parse_data
[2025-05-05T17:31:20.598+0300] {task_command.py:423} INFO - Running <TaskInstance: etl_pipeline.parse_data manual__2025-05-05T13:47:29.321134+00:00 [running]> on host macbook-air-admin.local
[2025-05-05T17:31:20.625+0300] {taskinstance.py:2513} INFO - Exporting env vars: AIRFLOW_CTX_DAG_OWNER='Bushueva Tatiana' AIRFLOW_CTX_DAG_ID='etl_pipeline' AIRFLOW_CTX_TASK_ID='parse_data' AIRFLOW_CTX_EXECUTION_DATE='2025-05-05T13:47:29.321134+00:00' AIRFLOW_CTX_TRY_NUMBER='1' AIRFLOW_CTX_DAG_RUN_ID='manual__2025-05-05T13:47:29.321134+00:00'
[2025-05-05T17:32:51.103+0300] {logging_mixin.py:188} INFO - Ошибка на странице 1: Message: invalid session id: session deleted as the browser has closed the connection
from disconnected: not connected to DevTools
  (Session info: chrome=135.0.7049.115)
Stacktrace:
0   chromedriver                        0x00000001011eaa54 cxxbridge1$str$ptr + 2803960
1   chromedriver                        0x00000001011e2cf0 cxxbridge1$str$ptr + 2771860
2   chromedriver                        0x0000000100d2e864 cxxbridge1$string$len + 93028
3   chromedriver                        0x0000000100d178f8 chromedriver + 194808
4   chromedriver                        0x0000000100d3b238 cxxbridge1$string$len + 144696
5   chromedriver                        0x0000000100d9d544 cxxbridge1$string$len + 546884
6   chromedriver                        0x0000000100db5f8c cxxbridge1$string$len + 647820
7   chromedriver                        0x0000000100d697ec cxxbridge1$string$len + 334572
8   chromedriver                        0x00000001011afccc cxxbridge1$str$ptr + 2562928
9   chromedriver                        0x00000001011b2f98 cxxbridge1$str$ptr + 2575932
10  chromedriver                        0x00000001011902c4 cxxbridge1$str$ptr + 2433384
11  chromedriver                        0x00000001011b3810 cxxbridge1$str$ptr + 2578100
12  chromedriver                        0x00000001011812f0 cxxbridge1$str$ptr + 2371988
13  chromedriver                        0x00000001011d357c cxxbridge1$str$ptr + 2708512
14  chromedriver                        0x00000001011d3708 cxxbridge1$str$ptr + 2708908
15  chromedriver                        0x00000001011e293c cxxbridge1$str$ptr + 2770912
16  libsystem_pthread.dylib             0x000000018b77f034 _pthread_start + 136
17  libsystem_pthread.dylib             0x000000018b779e3c thread_start + 8
[2025-05-05T17:32:51.109+0300] {logging_mixin.py:188} INFO - Данные сохранены в файл 0_page_.json
[2025-05-05T17:32:51.196+0300] {taskinstance.py:2731} ERROR - Task failed with exception
Traceback (most recent call last):
  File "/Users/admin/airflow/dags/scripts/parse_data.py", line 61, in data_pars
    elements = driver.find_elements(By.XPATH, '//*[@id="app"]/div/div[3]/div[1]/div/div[2]/div[3]/div/div[1]/div[2]/div[5]/div/article/p/span[1]')
               ^^^^^^^^^^^^^^^^^^^^^^^^^^^^^^^^^^^^^^^^^^^^^^^^^^^^^^^^^^^^^^^^^^^^^^^^^^^^^^^^^^^^^^^^^^^^^^^^^^^^^^^^^^^^^^^^^^^^^^^^^^^^^^^^^^^
  File "/Users/admin/anaconda3/lib/python3.11/site-packages/selenium/webdriver/remote/webdriver.py", line 778, in find_elements
    return self.execute(Command.FIND_ELEMENTS, {"using": by, "value": value})["value"] or []
           ^^^^^^^^^^^^^^^^^^^^^^^^^^^^^^^^^^^^^^^^^^^^^^^^^^^^^^^^^^^^^^^^^^
  File "/Users/admin/anaconda3/lib/python3.11/site-packages/selenium/webdriver/remote/webdriver.py", line 354, in execute
    self.error_handler.check_response(response)
  File "/Users/admin/anaconda3/lib/python3.11/site-packages/selenium/webdriver/remote/errorhandler.py", line 229, in check_response
    raise exception_class(message, screen, stacktrace)
selenium.common.exceptions.InvalidSessionIdException: Message: invalid session id: session deleted as the browser has closed the connection
from disconnected: not connected to DevTools
  (Session info: chrome=135.0.7049.115)
Stacktrace:
0   chromedriver                        0x00000001011eaa54 cxxbridge1$str$ptr + 2803960
1   chromedriver                        0x00000001011e2cf0 cxxbridge1$str$ptr + 2771860
2   chromedriver                        0x0000000100d2e864 cxxbridge1$string$len + 93028
3   chromedriver                        0x0000000100d178f8 chromedriver + 194808
4   chromedriver                        0x0000000100d3b238 cxxbridge1$string$len + 144696
5   chromedriver                        0x0000000100d9d544 cxxbridge1$string$len + 546884
6   chromedriver                        0x0000000100db5f8c cxxbridge1$string$len + 647820
7   chromedriver                        0x0000000100d697ec cxxbridge1$string$len + 334572
8   chromedriver                        0x00000001011afccc cxxbridge1$str$ptr + 2562928
9   chromedriver                        0x00000001011b2f98 cxxbridge1$str$ptr + 2575932
10  chromedriver                        0x00000001011902c4 cxxbridge1$str$ptr + 2433384
11  chromedriver                        0x00000001011b3810 cxxbridge1$str$ptr + 2578100
12  chromedriver                        0x00000001011812f0 cxxbridge1$str$ptr + 2371988
13  chromedriver                        0x00000001011d357c cxxbridge1$str$ptr + 2708512
14  chromedriver                        0x00000001011d3708 cxxbridge1$str$ptr + 2708908
15  chromedriver                        0x00000001011e293c cxxbridge1$str$ptr + 2770912
16  libsystem_pthread.dylib             0x000000018b77f034 _pthread_start + 136
17  libsystem_pthread.dylib             0x000000018b779e3c thread_start + 8


During handling of the above exception, another exception occurred:

Traceback (most recent call last):
  File "/Users/admin/anaconda3/lib/python3.11/site-packages/airflow/models/taskinstance.py", line 444, in _execute_task
    result = _execute_callable(context=context, **execute_callable_kwargs)
             ^^^^^^^^^^^^^^^^^^^^^^^^^^^^^^^^^^^^^^^^^^^^^^^^^^^^^^^^^^^^^
  File "/Users/admin/anaconda3/lib/python3.11/site-packages/airflow/models/taskinstance.py", line 414, in _execute_callable
    return execute_callable(context=context, **execute_callable_kwargs)
           ^^^^^^^^^^^^^^^^^^^^^^^^^^^^^^^^^^^^^^^^^^^^^^^^^^^^^^^^^^^^
  File "/Users/admin/anaconda3/lib/python3.11/site-packages/airflow/operators/python.py", line 200, in execute
    return_value = self.execute_callable()
                   ^^^^^^^^^^^^^^^^^^^^^^^
  File "/Users/admin/anaconda3/lib/python3.11/site-packages/airflow/operators/python.py", line 217, in execute_callable
    return self.python_callable(*self.op_args, **self.op_kwargs)
           ^^^^^^^^^^^^^^^^^^^^^^^^^^^^^^^^^^^^^^^^^^^^^^^^^^^^^
  File "/Users/admin/airflow/dags/etc_pipline.py", line 39, in _parse
    parsed = data_pars('https://www.avito.ru/all/rezume?cd=1&q=%D0%BA%D0%BE%D1%81%D0%BC%D0%B5%D1%82%D0%BE%D0%BB%D0%BE%D0%B3+%D1%80%D0%B5%D0%B7%D1%8E%D0%BC%D0%B5')
             ^^^^^^^^^^^^^^^^^^^^^^^^^^^^^^^^^^^^^^^^^^^^^^^^^^^^^^^^^^^^^^^^^^^^^^^^^^^^^^^^^^^^^^^^^^^^^^^^^^^^^^^^^^^^^^^^^^^^^^^^^^^^^^^^^^^^^^^^^^^^^^^^^^^^^
  File "/Users/admin/airflow/dags/scripts/parse_data.py", line 102, in data_pars
    driver.get(current_url)
  File "/Users/admin/anaconda3/lib/python3.11/site-packages/selenium/webdriver/remote/webdriver.py", line 363, in get
    self.execute(Command.GET, {"url": url})
  File "/Users/admin/anaconda3/lib/python3.11/site-packages/selenium/webdriver/remote/webdriver.py", line 354, in execute
    self.error_handler.check_response(response)
  File "/Users/admin/anaconda3/lib/python3.11/site-packages/selenium/webdriver/remote/errorhandler.py", line 229, in check_response
    raise exception_class(message, screen, stacktrace)
selenium.common.exceptions.InvalidSessionIdException: Message: invalid session id
Stacktrace:
0   chromedriver                        0x00000001011eaa54 cxxbridge1$str$ptr + 2803960
1   chromedriver                        0x00000001011e2cf0 cxxbridge1$str$ptr + 2771860
2   chromedriver                        0x0000000100d2e6d8 cxxbridge1$string$len + 92632
3   chromedriver                        0x0000000100d68c34 cxxbridge1$string$len + 331572
4   chromedriver                        0x0000000100d91030 cxxbridge1$string$len + 496432
5   chromedriver                        0x0000000100d90338 cxxbridge1$string$len + 493112
6   chromedriver                        0x0000000100cfe9ec chromedriver + 92652
7   chromedriver                        0x00000001011afccc cxxbridge1$str$ptr + 2562928
8   chromedriver                        0x00000001011b2f98 cxxbridge1$str$ptr + 2575932
9   chromedriver                        0x00000001011902c4 cxxbridge1$str$ptr + 2433384
10  chromedriver                        0x00000001011b3810 cxxbridge1$str$ptr + 2578100
11  chromedriver                        0x00000001011812f0 cxxbridge1$str$ptr + 2371988
12  chromedriver                        0x0000000100cfcc7c chromedriver + 85116
13  dyld                                0x000000018b405058 start + 2224

[2025-05-05T17:32:51.208+0300] {taskinstance.py:1149} INFO - Marking task as UP_FOR_RETRY. dag_id=etl_pipeline, task_id=parse_data, execution_date=20250505T134729, start_date=20250505T143120, end_date=20250505T143251
[2025-05-05T17:32:51.216+0300] {standard_task_runner.py:107} ERROR - Failed to execute job 25 for task parse_data (Message: invalid session id
Stacktrace:
0   chromedriver                        0x00000001011eaa54 cxxbridge1$str$ptr + 2803960
1   chromedriver                        0x00000001011e2cf0 cxxbridge1$str$ptr + 2771860
2   chromedriver                        0x0000000100d2e6d8 cxxbridge1$string$len + 92632
3   chromedriver                        0x0000000100d68c34 cxxbridge1$string$len + 331572
4   chromedriver                        0x0000000100d91030 cxxbridge1$string$len + 496432
5   chromedriver                        0x0000000100d90338 cxxbridge1$string$len + 493112
6   chromedriver                        0x0000000100cfe9ec chromedriver + 92652
7   chromedriver                        0x00000001011afccc cxxbridge1$str$ptr + 2562928
8   chromedriver                        0x00000001011b2f98 cxxbridge1$str$ptr + 2575932
9   chromedriver                        0x00000001011902c4 cxxbridge1$str$ptr + 2433384
10  chromedriver                        0x00000001011b3810 cxxbridge1$str$ptr + 2578100
11  chromedriver                        0x00000001011812f0 cxxbridge1$str$ptr + 2371988
12  chromedriver                        0x0000000100cfcc7c chromedriver + 85116
13  dyld                                0x000000018b405058 start + 2224
; 79187)
[2025-05-05T17:32:51.260+0300] {local_task_job_runner.py:234} INFO - Task exited with return code 1
[2025-05-05T17:32:51.273+0300] {taskinstance.py:3312} INFO - 0 downstream tasks scheduled from follow-on schedule check
