[2025-05-05T17:30:48.398+0300] {taskinstance.py:1979} INFO - Dependencies all met for dep_context=non-requeueable deps ti=<TaskInstance: etl_pipeline.evaluate_model manual__2025-05-05T10:58:32.357033+00:00 [queued]>
[2025-05-05T17:30:48.402+0300] {taskinstance.py:1979} INFO - Dependencies all met for dep_context=requeueable deps ti=<TaskInstance: etl_pipeline.evaluate_model manual__2025-05-05T10:58:32.357033+00:00 [queued]>
[2025-05-05T17:30:48.402+0300] {taskinstance.py:2193} INFO - Starting attempt 2 of 2
[2025-05-05T17:30:48.408+0300] {taskinstance.py:2217} INFO - Executing <Task(PythonOperator): evaluate_model> on 2025-05-05 10:58:32.357033+00:00
[2025-05-05T17:30:48.418+0300] {standard_task_runner.py:60} INFO - Started process 79031 to run task
[2025-05-05T17:30:48.426+0300] {standard_task_runner.py:87} INFO - Running: ['airflow', 'tasks', 'run', 'etl_pipeline', 'evaluate_model', 'manual__2025-05-05T10:58:32.357033+00:00', '--job-id', '24', '--raw', '--subdir', 'DAGS_FOLDER/etc_pipline.py', '--cfg-path', '/var/folders/rn/6d4yq54d3pz0b5ryq64xt07m0000gn/T/tmpent746cq']
[2025-05-05T17:30:48.427+0300] {standard_task_runner.py:88} INFO - Job 24: Subtask evaluate_model
[2025-05-05T17:30:48.466+0300] {task_command.py:423} INFO - Running <TaskInstance: etl_pipeline.evaluate_model manual__2025-05-05T10:58:32.357033+00:00 [running]> on host macbook-air-admin.local
[2025-05-05T17:30:48.497+0300] {taskinstance.py:2513} INFO - Exporting env vars: AIRFLOW_CTX_DAG_OWNER='Bushueva Tatiana' AIRFLOW_CTX_DAG_ID='etl_pipeline' AIRFLOW_CTX_TASK_ID='evaluate_model' AIRFLOW_CTX_EXECUTION_DATE='2025-05-05T10:58:32.357033+00:00' AIRFLOW_CTX_TRY_NUMBER='2' AIRFLOW_CTX_DAG_RUN_ID='manual__2025-05-05T10:58:32.357033+00:00'
[2025-05-05T17:30:48.502+0300] {taskinstance.py:2731} ERROR - Task failed with exception
Traceback (most recent call last):
  File "/Users/admin/anaconda3/lib/python3.11/site-packages/airflow/models/taskinstance.py", line 444, in _execute_task
    result = _execute_callable(context=context, **execute_callable_kwargs)
             ^^^^^^^^^^^^^^^^^^^^^^^^^^^^^^^^^^^^^^^^^^^^^^^^^^^^^^^^^^^^^
  File "/Users/admin/anaconda3/lib/python3.11/site-packages/airflow/models/taskinstance.py", line 414, in _execute_callable
    return execute_callable(context=context, **execute_callable_kwargs)
           ^^^^^^^^^^^^^^^^^^^^^^^^^^^^^^^^^^^^^^^^^^^^^^^^^^^^^^^^^^^^
  File "/Users/admin/anaconda3/lib/python3.11/site-packages/airflow/operators/python.py", line 200, in execute
    return_value = self.execute_callable()
                   ^^^^^^^^^^^^^^^^^^^^^^^
  File "/Users/admin/anaconda3/lib/python3.11/site-packages/airflow/operators/python.py", line 217, in execute_callable
    return self.python_callable(*self.op_args, **self.op_kwargs)
           ^^^^^^^^^^^^^^^^^^^^^^^^^^^^^^^^^^^^^^^^^^^^^^^^^^^^^
  File "/Users/admin/airflow/dags/etc_pipline.py", line 56, in _evaluate
    results = evaluate_model(parsed)
              ^^^^^^^^^^^^^^^^^^^^^^
  File "/Users/admin/airflow/dags/scripts/evaluate_model.py", line 77, in evaluate_model
    wandb.init(project="my_etl_project",job_type="evaluation",config={ "num_samples": len(data),})
                                                                                      ^^^^^^^^^
TypeError: object of type 'NoneType' has no len()
[2025-05-05T17:30:48.505+0300] {taskinstance.py:1149} INFO - Marking task as FAILED. dag_id=etl_pipeline, task_id=evaluate_model, execution_date=20250505T105832, start_date=20250505T143048, end_date=20250505T143048
[2025-05-05T17:30:48.509+0300] {standard_task_runner.py:107} ERROR - Failed to execute job 24 for task evaluate_model (object of type 'NoneType' has no len(); 79031)
[2025-05-05T17:30:48.525+0300] {local_task_job_runner.py:234} INFO - Task exited with return code 1
[2025-05-05T17:30:48.537+0300] {taskinstance.py:3312} INFO - 0 downstream tasks scheduled from follow-on schedule check
