[2025-05-04T23:21:01.356+0300] {processor.py:161} INFO - Started process (PID=19736) to work on /Users/admin/airflow/dags/etc_pipline.py
[2025-05-04T23:21:01.356+0300] {processor.py:830} INFO - Processing file /Users/admin/airflow/dags/etc_pipline.py for tasks to queue
[2025-05-04T23:21:01.357+0300] {logging_mixin.py:188} INFO - [2025-05-04T23:21:01.357+0300] {dagbag.py:540} INFO - Filling up the DagBag from /Users/admin/airflow/dags/etc_pipline.py
[2025-05-04T23:21:01.359+0300] {logging_mixin.py:188} INFO - [2025-05-04T23:21:01.358+0300] {dagbag.py:350} ERROR - Failed to import: /Users/admin/airflow/dags/etc_pipline.py
Traceback (most recent call last):
  File "/Users/admin/anaconda3/lib/python3.11/site-packages/airflow/models/dagbag.py", line 346, in parse
    loader.exec_module(new_module)
  File "<frozen importlib._bootstrap_external>", line 940, in exec_module
  File "<frozen importlib._bootstrap>", line 241, in _call_with_frames_removed
  File "/Users/admin/airflow/dags/etc_pipline.py", line 5, in <module>
    "execution_count": null,
                       ^^^^
NameError: name 'null' is not defined
[2025-05-04T23:21:01.359+0300] {processor.py:842} WARNING - No viable dags retrieved from /Users/admin/airflow/dags/etc_pipline.py
[2025-05-04T23:21:01.412+0300] {processor.py:183} INFO - Processing /Users/admin/airflow/dags/etc_pipline.py took 0.056 seconds
[2025-05-04T23:22:35.081+0300] {processor.py:161} INFO - Started process (PID=20177) to work on /Users/admin/airflow/dags/etc_pipline.py
[2025-05-04T23:22:35.082+0300] {processor.py:830} INFO - Processing file /Users/admin/airflow/dags/etc_pipline.py for tasks to queue
[2025-05-04T23:22:35.083+0300] {logging_mixin.py:188} INFO - [2025-05-04T23:22:35.083+0300] {dagbag.py:540} INFO - Filling up the DagBag from /Users/admin/airflow/dags/etc_pipline.py
[2025-05-04T23:22:35.468+0300] {logging_mixin.py:188} INFO - [2025-05-04T23:22:35.468+0300] {utils.py:160} INFO - NumExpr defaulting to 8 threads.
[2025-05-04T23:22:35.745+0300] {logging_mixin.py:188} INFO - [2025-05-04T23:22:35.744+0300] {dagbag.py:350} ERROR - Failed to import: /Users/admin/airflow/dags/etc_pipline.py
Traceback (most recent call last):
  File "/Users/admin/anaconda3/lib/python3.11/site-packages/airflow/models/dagbag.py", line 346, in parse
    loader.exec_module(new_module)
  File "<frozen importlib._bootstrap_external>", line 940, in exec_module
  File "<frozen importlib._bootstrap>", line 241, in _call_with_frames_removed
  File "/Users/admin/airflow/dags/etc_pipline.py", line 8, in <module>
    from scripts import evaluate_model
  File "/Users/admin/airflow/dags/scripts/evaluate_model.py", line 13
    wandb login '118570a17fac7c4cffe0ad0c784f09cf67222d20'
          ^^^^^
SyntaxError: invalid syntax
[2025-05-04T23:22:35.745+0300] {processor.py:842} WARNING - No viable dags retrieved from /Users/admin/airflow/dags/etc_pipline.py
[2025-05-04T23:22:35.792+0300] {processor.py:183} INFO - Processing /Users/admin/airflow/dags/etc_pipline.py took 0.711 seconds
[2025-05-04T23:24:00.588+0300] {processor.py:161} INFO - Started process (PID=20582) to work on /Users/admin/airflow/dags/etc_pipline.py
[2025-05-04T23:24:00.589+0300] {processor.py:830} INFO - Processing file /Users/admin/airflow/dags/etc_pipline.py for tasks to queue
[2025-05-04T23:24:00.590+0300] {logging_mixin.py:188} INFO - [2025-05-04T23:24:00.590+0300] {dagbag.py:540} INFO - Filling up the DagBag from /Users/admin/airflow/dags/etc_pipline.py
[2025-05-04T23:24:00.998+0300] {logging_mixin.py:188} INFO - [2025-05-04T23:24:00.997+0300] {utils.py:160} INFO - NumExpr defaulting to 8 threads.
[2025-05-04T23:24:01.266+0300] {logging_mixin.py:188} INFO - [2025-05-04T23:24:01.265+0300] {dagbag.py:350} ERROR - Failed to import: /Users/admin/airflow/dags/etc_pipline.py
Traceback (most recent call last):
  File "/Users/admin/anaconda3/lib/python3.11/site-packages/airflow/models/dagbag.py", line 346, in parse
    loader.exec_module(new_module)
  File "<frozen importlib._bootstrap_external>", line 940, in exec_module
  File "<frozen importlib._bootstrap>", line 241, in _call_with_frames_removed
  File "/Users/admin/airflow/dags/etc_pipline.py", line 8, in <module>
    from scripts import evaluate_model
  File "/Users/admin/airflow/dags/scripts/evaluate_model.py", line 13
    wandb login '118570a17fac7c4cffe0ad0c784f09cf67222d20'
          ^^^^^
SyntaxError: invalid syntax
[2025-05-04T23:24:01.267+0300] {processor.py:842} WARNING - No viable dags retrieved from /Users/admin/airflow/dags/etc_pipline.py
[2025-05-04T23:24:01.314+0300] {processor.py:183} INFO - Processing /Users/admin/airflow/dags/etc_pipline.py took 0.727 seconds
[2025-05-04T23:25:27.324+0300] {processor.py:161} INFO - Started process (PID=20985) to work on /Users/admin/airflow/dags/etc_pipline.py
[2025-05-04T23:25:27.326+0300] {processor.py:830} INFO - Processing file /Users/admin/airflow/dags/etc_pipline.py for tasks to queue
[2025-05-04T23:25:27.326+0300] {logging_mixin.py:188} INFO - [2025-05-04T23:25:27.326+0300] {dagbag.py:540} INFO - Filling up the DagBag from /Users/admin/airflow/dags/etc_pipline.py
[2025-05-04T23:25:27.721+0300] {logging_mixin.py:188} INFO - [2025-05-04T23:25:27.721+0300] {utils.py:160} INFO - NumExpr defaulting to 8 threads.
[2025-05-04T23:25:27.986+0300] {logging_mixin.py:188} INFO - [2025-05-04T23:25:27.985+0300] {dagbag.py:350} ERROR - Failed to import: /Users/admin/airflow/dags/etc_pipline.py
Traceback (most recent call last):
  File "/Users/admin/anaconda3/lib/python3.11/site-packages/airflow/models/dagbag.py", line 346, in parse
    loader.exec_module(new_module)
  File "<frozen importlib._bootstrap_external>", line 940, in exec_module
  File "<frozen importlib._bootstrap>", line 241, in _call_with_frames_removed
  File "/Users/admin/airflow/dags/etc_pipline.py", line 8, in <module>
    from scripts import evaluate_model
  File "/Users/admin/airflow/dags/scripts/evaluate_model.py", line 13
    !wandb login '118570a17fac7c4cffe0ad0c784f09cf67222d20'
    ^
SyntaxError: invalid syntax
[2025-05-04T23:25:27.987+0300] {processor.py:842} WARNING - No viable dags retrieved from /Users/admin/airflow/dags/etc_pipline.py
[2025-05-04T23:25:28.033+0300] {processor.py:183} INFO - Processing /Users/admin/airflow/dags/etc_pipline.py took 0.710 seconds
[2025-05-04T23:26:54.268+0300] {processor.py:161} INFO - Started process (PID=21404) to work on /Users/admin/airflow/dags/etc_pipline.py
[2025-05-04T23:26:54.268+0300] {processor.py:830} INFO - Processing file /Users/admin/airflow/dags/etc_pipline.py for tasks to queue
[2025-05-04T23:26:54.269+0300] {logging_mixin.py:188} INFO - [2025-05-04T23:26:54.269+0300] {dagbag.py:540} INFO - Filling up the DagBag from /Users/admin/airflow/dags/etc_pipline.py
[2025-05-04T23:26:54.709+0300] {logging_mixin.py:188} INFO - [2025-05-04T23:26:54.709+0300] {utils.py:160} INFO - NumExpr defaulting to 8 threads.
[2025-05-04T23:26:54.988+0300] {logging_mixin.py:188} INFO - [2025-05-04T23:26:54.987+0300] {dagbag.py:350} ERROR - Failed to import: /Users/admin/airflow/dags/etc_pipline.py
Traceback (most recent call last):
  File "/Users/admin/anaconda3/lib/python3.11/site-packages/airflow/models/dagbag.py", line 346, in parse
    loader.exec_module(new_module)
  File "<frozen importlib._bootstrap_external>", line 940, in exec_module
  File "<frozen importlib._bootstrap>", line 241, in _call_with_frames_removed
  File "/Users/admin/airflow/dags/etc_pipline.py", line 8, in <module>
    from scripts import evaluate_model
  File "/Users/admin/airflow/dags/scripts/evaluate_model.py", line 13
    !wandb login '118570a17fac7c4cffe0ad0c784f09cf67222d20'
    ^
SyntaxError: invalid syntax
[2025-05-04T23:26:54.988+0300] {processor.py:842} WARNING - No viable dags retrieved from /Users/admin/airflow/dags/etc_pipline.py
[2025-05-04T23:26:55.035+0300] {processor.py:183} INFO - Processing /Users/admin/airflow/dags/etc_pipline.py took 0.768 seconds
[2025-05-04T23:28:20.556+0300] {processor.py:161} INFO - Started process (PID=21811) to work on /Users/admin/airflow/dags/etc_pipline.py
[2025-05-04T23:28:20.557+0300] {processor.py:830} INFO - Processing file /Users/admin/airflow/dags/etc_pipline.py for tasks to queue
[2025-05-04T23:28:20.557+0300] {logging_mixin.py:188} INFO - [2025-05-04T23:28:20.557+0300] {dagbag.py:540} INFO - Filling up the DagBag from /Users/admin/airflow/dags/etc_pipline.py
[2025-05-04T23:28:20.794+0300] {logging_mixin.py:188} INFO - [2025-05-04T23:28:20.794+0300] {utils.py:160} INFO - NumExpr defaulting to 8 threads.
[2025-05-04T23:28:21.016+0300] {logging_mixin.py:188} INFO - [2025-05-04T23:28:21.016+0300] {dagbag.py:350} ERROR - Failed to import: /Users/admin/airflow/dags/etc_pipline.py
Traceback (most recent call last):
  File "/Users/admin/anaconda3/lib/python3.11/site-packages/airflow/models/dagbag.py", line 346, in parse
    loader.exec_module(new_module)
  File "<frozen importlib._bootstrap_external>", line 940, in exec_module
  File "<frozen importlib._bootstrap>", line 241, in _call_with_frames_removed
  File "/Users/admin/airflow/dags/etc_pipline.py", line 8, in <module>
    from scripts import evaluate_model
  File "/Users/admin/airflow/dags/scripts/evaluate_model.py", line 13
    wandb.login '118570a17fac7c4cffe0ad0c784f09cf67222d20'
                ^^^^^^^^^^^^^^^^^^^^^^^^^^^^^^^^^^^^^^^^^^
SyntaxError: invalid syntax
[2025-05-04T23:28:21.017+0300] {processor.py:842} WARNING - No viable dags retrieved from /Users/admin/airflow/dags/etc_pipline.py
[2025-05-04T23:28:21.063+0300] {processor.py:183} INFO - Processing /Users/admin/airflow/dags/etc_pipline.py took 0.508 seconds
[2025-05-04T23:29:51.278+0300] {processor.py:161} INFO - Started process (PID=22257) to work on /Users/admin/airflow/dags/etc_pipline.py
[2025-05-04T23:29:51.279+0300] {processor.py:830} INFO - Processing file /Users/admin/airflow/dags/etc_pipline.py for tasks to queue
[2025-05-04T23:29:51.280+0300] {logging_mixin.py:188} INFO - [2025-05-04T23:29:51.280+0300] {dagbag.py:540} INFO - Filling up the DagBag from /Users/admin/airflow/dags/etc_pipline.py
[2025-05-04T23:29:51.724+0300] {logging_mixin.py:188} INFO - [2025-05-04T23:29:51.724+0300] {utils.py:160} INFO - NumExpr defaulting to 8 threads.
[2025-05-04T23:29:52.002+0300] {logging_mixin.py:188} INFO - [2025-05-04T23:29:52.001+0300] {dagbag.py:350} ERROR - Failed to import: /Users/admin/airflow/dags/etc_pipline.py
Traceback (most recent call last):
  File "/Users/admin/anaconda3/lib/python3.11/site-packages/airflow/models/dagbag.py", line 346, in parse
    loader.exec_module(new_module)
  File "<frozen importlib._bootstrap_external>", line 940, in exec_module
  File "<frozen importlib._bootstrap>", line 241, in _call_with_frames_removed
  File "/Users/admin/airflow/dags/etc_pipline.py", line 8, in <module>
    from scripts import evaluate_model
  File "/Users/admin/airflow/dags/scripts/evaluate_model.py", line 13
    wandb.login '118570a17fac7c4cffe0ad0c784f09cf67222d20'
                ^^^^^^^^^^^^^^^^^^^^^^^^^^^^^^^^^^^^^^^^^^
SyntaxError: invalid syntax
[2025-05-04T23:29:52.002+0300] {processor.py:842} WARNING - No viable dags retrieved from /Users/admin/airflow/dags/etc_pipline.py
[2025-05-04T23:29:52.049+0300] {processor.py:183} INFO - Processing /Users/admin/airflow/dags/etc_pipline.py took 0.772 seconds
[2025-05-04T23:31:21.208+0300] {processor.py:161} INFO - Started process (PID=22679) to work on /Users/admin/airflow/dags/etc_pipline.py
[2025-05-04T23:31:21.209+0300] {processor.py:830} INFO - Processing file /Users/admin/airflow/dags/etc_pipline.py for tasks to queue
[2025-05-04T23:31:21.209+0300] {logging_mixin.py:188} INFO - [2025-05-04T23:31:21.209+0300] {dagbag.py:540} INFO - Filling up the DagBag from /Users/admin/airflow/dags/etc_pipline.py
[2025-05-04T23:31:21.725+0300] {logging_mixin.py:188} INFO - [2025-05-04T23:31:21.725+0300] {utils.py:160} INFO - NumExpr defaulting to 8 threads.
[2025-05-04T23:31:22.000+0300] {logging_mixin.py:188} INFO - [2025-05-04T23:31:21.999+0300] {dagbag.py:350} ERROR - Failed to import: /Users/admin/airflow/dags/etc_pipline.py
Traceback (most recent call last):
  File "/Users/admin/anaconda3/lib/python3.11/site-packages/airflow/models/dagbag.py", line 346, in parse
    loader.exec_module(new_module)
  File "<frozen importlib._bootstrap_external>", line 940, in exec_module
  File "<frozen importlib._bootstrap>", line 241, in _call_with_frames_removed
  File "/Users/admin/airflow/dags/etc_pipline.py", line 8, in <module>
    from scripts import evaluate_model
  File "/Users/admin/airflow/dags/scripts/evaluate_model.py", line 13
    wandb.login '118570a17fac7c4cffe0ad0c784f09cf67222d20'
                ^^^^^^^^^^^^^^^^^^^^^^^^^^^^^^^^^^^^^^^^^^
SyntaxError: invalid syntax
[2025-05-04T23:31:22.000+0300] {processor.py:842} WARNING - No viable dags retrieved from /Users/admin/airflow/dags/etc_pipline.py
[2025-05-04T23:31:22.048+0300] {processor.py:183} INFO - Processing /Users/admin/airflow/dags/etc_pipline.py took 0.841 seconds
[2025-05-04T23:32:50.651+0300] {processor.py:161} INFO - Started process (PID=23097) to work on /Users/admin/airflow/dags/etc_pipline.py
[2025-05-04T23:32:50.652+0300] {processor.py:830} INFO - Processing file /Users/admin/airflow/dags/etc_pipline.py for tasks to queue
[2025-05-04T23:32:50.652+0300] {logging_mixin.py:188} INFO - [2025-05-04T23:32:50.652+0300] {dagbag.py:540} INFO - Filling up the DagBag from /Users/admin/airflow/dags/etc_pipline.py
[2025-05-04T23:32:51.051+0300] {logging_mixin.py:188} INFO - [2025-05-04T23:32:51.050+0300] {utils.py:160} INFO - NumExpr defaulting to 8 threads.
[2025-05-04T23:32:51.340+0300] {logging_mixin.py:188} INFO - [2025-05-04T23:32:51.339+0300] {dagbag.py:350} ERROR - Failed to import: /Users/admin/airflow/dags/etc_pipline.py
Traceback (most recent call last):
  File "/Users/admin/anaconda3/lib/python3.11/site-packages/airflow/models/dagbag.py", line 346, in parse
    loader.exec_module(new_module)
  File "<frozen importlib._bootstrap_external>", line 940, in exec_module
  File "<frozen importlib._bootstrap>", line 241, in _call_with_frames_removed
  File "/Users/admin/airflow/dags/etc_pipline.py", line 8, in <module>
    from scripts import evaluate_model
  File "/Users/admin/airflow/dags/scripts/evaluate_model.py", line 13
    wandb.login '118570a17fac7c4cffe0ad0c784f09cf67222d20'
                ^^^^^^^^^^^^^^^^^^^^^^^^^^^^^^^^^^^^^^^^^^
SyntaxError: invalid syntax
[2025-05-04T23:32:51.340+0300] {processor.py:842} WARNING - No viable dags retrieved from /Users/admin/airflow/dags/etc_pipline.py
[2025-05-04T23:32:51.390+0300] {processor.py:183} INFO - Processing /Users/admin/airflow/dags/etc_pipline.py took 0.740 seconds
[2025-05-04T23:34:18.012+0300] {processor.py:161} INFO - Started process (PID=23502) to work on /Users/admin/airflow/dags/etc_pipline.py
[2025-05-04T23:34:18.013+0300] {processor.py:830} INFO - Processing file /Users/admin/airflow/dags/etc_pipline.py for tasks to queue
[2025-05-04T23:34:18.014+0300] {logging_mixin.py:188} INFO - [2025-05-04T23:34:18.014+0300] {dagbag.py:540} INFO - Filling up the DagBag from /Users/admin/airflow/dags/etc_pipline.py
[2025-05-04T23:34:18.473+0300] {logging_mixin.py:188} INFO - [2025-05-04T23:34:18.473+0300] {utils.py:160} INFO - NumExpr defaulting to 8 threads.
[2025-05-04T23:34:18.752+0300] {logging_mixin.py:188} INFO - [2025-05-04T23:34:18.751+0300] {dagbag.py:350} ERROR - Failed to import: /Users/admin/airflow/dags/etc_pipline.py
Traceback (most recent call last):
  File "/Users/admin/anaconda3/lib/python3.11/site-packages/airflow/models/dagbag.py", line 346, in parse
    loader.exec_module(new_module)
  File "<frozen importlib._bootstrap_external>", line 940, in exec_module
  File "<frozen importlib._bootstrap>", line 241, in _call_with_frames_removed
  File "/Users/admin/airflow/dags/etc_pipline.py", line 8, in <module>
    from scripts import evaluate_model
  File "/Users/admin/airflow/dags/scripts/evaluate_model.py", line 13
    wandb.login '118570a17fac7c4cffe0ad0c784f09cf67222d20'
                ^^^^^^^^^^^^^^^^^^^^^^^^^^^^^^^^^^^^^^^^^^
SyntaxError: invalid syntax
[2025-05-04T23:34:18.753+0300] {processor.py:842} WARNING - No viable dags retrieved from /Users/admin/airflow/dags/etc_pipline.py
[2025-05-04T23:34:18.799+0300] {processor.py:183} INFO - Processing /Users/admin/airflow/dags/etc_pipline.py took 0.788 seconds
[2025-05-04T23:35:53.310+0300] {processor.py:161} INFO - Started process (PID=23965) to work on /Users/admin/airflow/dags/etc_pipline.py
[2025-05-04T23:35:53.313+0300] {processor.py:830} INFO - Processing file /Users/admin/airflow/dags/etc_pipline.py for tasks to queue
[2025-05-04T23:35:53.313+0300] {logging_mixin.py:188} INFO - [2025-05-04T23:35:53.313+0300] {dagbag.py:540} INFO - Filling up the DagBag from /Users/admin/airflow/dags/etc_pipline.py
[2025-05-04T23:35:53.757+0300] {logging_mixin.py:188} INFO - [2025-05-04T23:35:53.757+0300] {utils.py:160} INFO - NumExpr defaulting to 8 threads.
[2025-05-04T23:35:54.048+0300] {logging_mixin.py:188} INFO - [2025-05-04T23:35:54.047+0300] {dagbag.py:350} ERROR - Failed to import: /Users/admin/airflow/dags/etc_pipline.py
Traceback (most recent call last):
  File "/Users/admin/anaconda3/lib/python3.11/site-packages/airflow/models/dagbag.py", line 346, in parse
    loader.exec_module(new_module)
  File "<frozen importlib._bootstrap_external>", line 940, in exec_module
  File "<frozen importlib._bootstrap>", line 241, in _call_with_frames_removed
  File "/Users/admin/airflow/dags/etc_pipline.py", line 8, in <module>
    from scripts import evaluate_model
  File "/Users/admin/airflow/dags/scripts/evaluate_model.py", line 13
    wandb.login '118570a17fac7c4cffe0ad0c784f09cf67222d20'
                ^^^^^^^^^^^^^^^^^^^^^^^^^^^^^^^^^^^^^^^^^^
SyntaxError: invalid syntax
[2025-05-04T23:35:54.048+0300] {processor.py:842} WARNING - No viable dags retrieved from /Users/admin/airflow/dags/etc_pipline.py
[2025-05-04T23:35:54.095+0300] {processor.py:183} INFO - Processing /Users/admin/airflow/dags/etc_pipline.py took 0.785 seconds
[2025-05-04T23:37:23.834+0300] {processor.py:161} INFO - Started process (PID=24406) to work on /Users/admin/airflow/dags/etc_pipline.py
[2025-05-04T23:37:23.835+0300] {processor.py:830} INFO - Processing file /Users/admin/airflow/dags/etc_pipline.py for tasks to queue
[2025-05-04T23:37:23.835+0300] {logging_mixin.py:188} INFO - [2025-05-04T23:37:23.835+0300] {dagbag.py:540} INFO - Filling up the DagBag from /Users/admin/airflow/dags/etc_pipline.py
[2025-05-04T23:37:24.221+0300] {logging_mixin.py:188} INFO - [2025-05-04T23:37:24.221+0300] {utils.py:160} INFO - NumExpr defaulting to 8 threads.
[2025-05-04T23:37:24.481+0300] {logging_mixin.py:188} INFO - [2025-05-04T23:37:24.480+0300] {dagbag.py:350} ERROR - Failed to import: /Users/admin/airflow/dags/etc_pipline.py
Traceback (most recent call last):
  File "/Users/admin/anaconda3/lib/python3.11/site-packages/airflow/models/dagbag.py", line 346, in parse
    loader.exec_module(new_module)
  File "<frozen importlib._bootstrap_external>", line 940, in exec_module
  File "<frozen importlib._bootstrap>", line 241, in _call_with_frames_removed
  File "/Users/admin/airflow/dags/etc_pipline.py", line 8, in <module>
    from scripts import evaluate_model
  File "/Users/admin/airflow/dags/scripts/evaluate_model.py", line 13
    wandb.login '118570a17fac7c4cffe0ad0c784f09cf67222d20'
                ^^^^^^^^^^^^^^^^^^^^^^^^^^^^^^^^^^^^^^^^^^
SyntaxError: invalid syntax
[2025-05-04T23:37:24.481+0300] {processor.py:842} WARNING - No viable dags retrieved from /Users/admin/airflow/dags/etc_pipline.py
[2025-05-04T23:37:24.528+0300] {processor.py:183} INFO - Processing /Users/admin/airflow/dags/etc_pipline.py took 0.695 seconds
[2025-05-04T23:38:53.523+0300] {processor.py:161} INFO - Started process (PID=24820) to work on /Users/admin/airflow/dags/etc_pipline.py
[2025-05-04T23:38:53.524+0300] {processor.py:830} INFO - Processing file /Users/admin/airflow/dags/etc_pipline.py for tasks to queue
[2025-05-04T23:38:53.525+0300] {logging_mixin.py:188} INFO - [2025-05-04T23:38:53.524+0300] {dagbag.py:540} INFO - Filling up the DagBag from /Users/admin/airflow/dags/etc_pipline.py
[2025-05-04T23:38:54.041+0300] {logging_mixin.py:188} INFO - [2025-05-04T23:38:54.041+0300] {utils.py:160} INFO - NumExpr defaulting to 8 threads.
[2025-05-04T23:38:54.327+0300] {logging_mixin.py:188} INFO - [2025-05-04T23:38:54.326+0300] {dagbag.py:350} ERROR - Failed to import: /Users/admin/airflow/dags/etc_pipline.py
Traceback (most recent call last):
  File "/Users/admin/anaconda3/lib/python3.11/site-packages/airflow/models/dagbag.py", line 346, in parse
    loader.exec_module(new_module)
  File "<frozen importlib._bootstrap_external>", line 940, in exec_module
  File "<frozen importlib._bootstrap>", line 241, in _call_with_frames_removed
  File "/Users/admin/airflow/dags/etc_pipline.py", line 8, in <module>
    from scripts import evaluate_model
  File "/Users/admin/airflow/dags/scripts/evaluate_model.py", line 13
    wandb.login '118570a17fac7c4cffe0ad0c784f09cf67222d20'
                ^^^^^^^^^^^^^^^^^^^^^^^^^^^^^^^^^^^^^^^^^^
SyntaxError: invalid syntax
[2025-05-04T23:38:54.328+0300] {processor.py:842} WARNING - No viable dags retrieved from /Users/admin/airflow/dags/etc_pipline.py
[2025-05-04T23:38:54.374+0300] {processor.py:183} INFO - Processing /Users/admin/airflow/dags/etc_pipline.py took 0.852 seconds
[2025-05-04T23:40:30.696+0300] {processor.py:161} INFO - Started process (PID=25283) to work on /Users/admin/airflow/dags/etc_pipline.py
[2025-05-04T23:40:30.697+0300] {processor.py:830} INFO - Processing file /Users/admin/airflow/dags/etc_pipline.py for tasks to queue
[2025-05-04T23:40:30.698+0300] {logging_mixin.py:188} INFO - [2025-05-04T23:40:30.697+0300] {dagbag.py:540} INFO - Filling up the DagBag from /Users/admin/airflow/dags/etc_pipline.py
[2025-05-04T23:40:31.290+0300] {logging_mixin.py:188} INFO - [2025-05-04T23:40:31.289+0300] {utils.py:160} INFO - NumExpr defaulting to 8 threads.
[2025-05-04T23:40:31.574+0300] {logging_mixin.py:188} INFO - [2025-05-04T23:40:31.573+0300] {dagbag.py:350} ERROR - Failed to import: /Users/admin/airflow/dags/etc_pipline.py
Traceback (most recent call last):
  File "/Users/admin/anaconda3/lib/python3.11/site-packages/airflow/models/dagbag.py", line 346, in parse
    loader.exec_module(new_module)
  File "<frozen importlib._bootstrap_external>", line 940, in exec_module
  File "<frozen importlib._bootstrap>", line 241, in _call_with_frames_removed
  File "/Users/admin/airflow/dags/etc_pipline.py", line 8, in <module>
    from scripts import evaluate_model
  File "/Users/admin/airflow/dags/scripts/evaluate_model.py", line 13
    wandb.login '118570a17fac7c4cffe0ad0c784f09cf67222d20'
                ^^^^^^^^^^^^^^^^^^^^^^^^^^^^^^^^^^^^^^^^^^
SyntaxError: invalid syntax
[2025-05-04T23:40:31.574+0300] {processor.py:842} WARNING - No viable dags retrieved from /Users/admin/airflow/dags/etc_pipline.py
[2025-05-04T23:40:31.635+0300] {processor.py:183} INFO - Processing /Users/admin/airflow/dags/etc_pipline.py took 0.940 seconds
[2025-05-04T23:42:14.743+0300] {processor.py:161} INFO - Started process (PID=25763) to work on /Users/admin/airflow/dags/etc_pipline.py
[2025-05-04T23:42:14.744+0300] {processor.py:830} INFO - Processing file /Users/admin/airflow/dags/etc_pipline.py for tasks to queue
[2025-05-04T23:42:14.745+0300] {logging_mixin.py:188} INFO - [2025-05-04T23:42:14.745+0300] {dagbag.py:540} INFO - Filling up the DagBag from /Users/admin/airflow/dags/etc_pipline.py
[2025-05-04T23:42:15.182+0300] {logging_mixin.py:188} INFO - [2025-05-04T23:42:15.182+0300] {utils.py:160} INFO - NumExpr defaulting to 8 threads.
[2025-05-04T23:42:15.452+0300] {logging_mixin.py:188} INFO - [2025-05-04T23:42:15.451+0300] {dagbag.py:350} ERROR - Failed to import: /Users/admin/airflow/dags/etc_pipline.py
Traceback (most recent call last):
  File "/Users/admin/anaconda3/lib/python3.11/site-packages/airflow/models/dagbag.py", line 346, in parse
    loader.exec_module(new_module)
  File "<frozen importlib._bootstrap_external>", line 940, in exec_module
  File "<frozen importlib._bootstrap>", line 241, in _call_with_frames_removed
  File "/Users/admin/airflow/dags/etc_pipline.py", line 8, in <module>
    from scripts import evaluate_model
  File "/Users/admin/airflow/dags/scripts/evaluate_model.py", line 13
    wandb.login '118570a17fac7c4cffe0ad0c784f09cf67222d20'
                ^^^^^^^^^^^^^^^^^^^^^^^^^^^^^^^^^^^^^^^^^^
SyntaxError: invalid syntax
[2025-05-04T23:42:15.453+0300] {processor.py:842} WARNING - No viable dags retrieved from /Users/admin/airflow/dags/etc_pipline.py
[2025-05-04T23:42:15.499+0300] {processor.py:183} INFO - Processing /Users/admin/airflow/dags/etc_pipline.py took 0.757 seconds
[2025-05-04T23:44:03.113+0300] {processor.py:161} INFO - Started process (PID=26263) to work on /Users/admin/airflow/dags/etc_pipline.py
[2025-05-04T23:44:03.115+0300] {processor.py:830} INFO - Processing file /Users/admin/airflow/dags/etc_pipline.py for tasks to queue
[2025-05-04T23:44:03.115+0300] {logging_mixin.py:188} INFO - [2025-05-04T23:44:03.115+0300] {dagbag.py:540} INFO - Filling up the DagBag from /Users/admin/airflow/dags/etc_pipline.py
[2025-05-04T23:44:03.546+0300] {logging_mixin.py:188} INFO - [2025-05-04T23:44:03.546+0300] {utils.py:160} INFO - NumExpr defaulting to 8 threads.
[2025-05-04T23:44:03.818+0300] {logging_mixin.py:188} INFO - [2025-05-04T23:44:03.817+0300] {dagbag.py:350} ERROR - Failed to import: /Users/admin/airflow/dags/etc_pipline.py
Traceback (most recent call last):
  File "/Users/admin/anaconda3/lib/python3.11/site-packages/airflow/models/dagbag.py", line 346, in parse
    loader.exec_module(new_module)
  File "<frozen importlib._bootstrap_external>", line 940, in exec_module
  File "<frozen importlib._bootstrap>", line 241, in _call_with_frames_removed
  File "/Users/admin/airflow/dags/etc_pipline.py", line 8, in <module>
    from scripts import evaluate_model
  File "/Users/admin/airflow/dags/scripts/evaluate_model.py", line 13
    wandb.login '118570a17fac7c4cffe0ad0c784f09cf67222d20'
                ^^^^^^^^^^^^^^^^^^^^^^^^^^^^^^^^^^^^^^^^^^
SyntaxError: invalid syntax
[2025-05-04T23:44:03.818+0300] {processor.py:842} WARNING - No viable dags retrieved from /Users/admin/airflow/dags/etc_pipline.py
[2025-05-04T23:44:03.866+0300] {processor.py:183} INFO - Processing /Users/admin/airflow/dags/etc_pipline.py took 0.753 seconds
[2025-05-04T23:45:36.548+0300] {processor.py:161} INFO - Started process (PID=26700) to work on /Users/admin/airflow/dags/etc_pipline.py
[2025-05-04T23:45:36.549+0300] {processor.py:830} INFO - Processing file /Users/admin/airflow/dags/etc_pipline.py for tasks to queue
[2025-05-04T23:45:36.550+0300] {logging_mixin.py:188} INFO - [2025-05-04T23:45:36.550+0300] {dagbag.py:540} INFO - Filling up the DagBag from /Users/admin/airflow/dags/etc_pipline.py
[2025-05-04T23:45:36.976+0300] {logging_mixin.py:188} INFO - [2025-05-04T23:45:36.976+0300] {utils.py:160} INFO - NumExpr defaulting to 8 threads.
[2025-05-04T23:45:37.235+0300] {logging_mixin.py:188} INFO - [2025-05-04T23:45:37.234+0300] {dagbag.py:350} ERROR - Failed to import: /Users/admin/airflow/dags/etc_pipline.py
Traceback (most recent call last):
  File "/Users/admin/anaconda3/lib/python3.11/site-packages/airflow/models/dagbag.py", line 346, in parse
    loader.exec_module(new_module)
  File "<frozen importlib._bootstrap_external>", line 940, in exec_module
  File "<frozen importlib._bootstrap>", line 241, in _call_with_frames_removed
  File "/Users/admin/airflow/dags/etc_pipline.py", line 8, in <module>
    from scripts import evaluate_model
  File "/Users/admin/airflow/dags/scripts/evaluate_model.py", line 13
    wandb.login '118570a17fac7c4cffe0ad0c784f09cf67222d20'
                ^^^^^^^^^^^^^^^^^^^^^^^^^^^^^^^^^^^^^^^^^^
SyntaxError: invalid syntax
[2025-05-04T23:45:37.236+0300] {processor.py:842} WARNING - No viable dags retrieved from /Users/admin/airflow/dags/etc_pipline.py
[2025-05-04T23:45:37.283+0300] {processor.py:183} INFO - Processing /Users/admin/airflow/dags/etc_pipline.py took 0.735 seconds
[2025-05-04T23:47:06.923+0300] {processor.py:161} INFO - Started process (PID=27115) to work on /Users/admin/airflow/dags/etc_pipline.py
[2025-05-04T23:47:06.924+0300] {processor.py:830} INFO - Processing file /Users/admin/airflow/dags/etc_pipline.py for tasks to queue
[2025-05-04T23:47:06.924+0300] {logging_mixin.py:188} INFO - [2025-05-04T23:47:06.924+0300] {dagbag.py:540} INFO - Filling up the DagBag from /Users/admin/airflow/dags/etc_pipline.py
[2025-05-04T23:47:07.327+0300] {logging_mixin.py:188} INFO - [2025-05-04T23:47:07.326+0300] {utils.py:160} INFO - NumExpr defaulting to 8 threads.
[2025-05-04T23:47:07.605+0300] {logging_mixin.py:188} INFO - [2025-05-04T23:47:07.604+0300] {dagbag.py:350} ERROR - Failed to import: /Users/admin/airflow/dags/etc_pipline.py
Traceback (most recent call last):
  File "/Users/admin/anaconda3/lib/python3.11/site-packages/airflow/models/dagbag.py", line 346, in parse
    loader.exec_module(new_module)
  File "<frozen importlib._bootstrap_external>", line 940, in exec_module
  File "<frozen importlib._bootstrap>", line 241, in _call_with_frames_removed
  File "/Users/admin/airflow/dags/etc_pipline.py", line 8, in <module>
    from scripts import evaluate_model
  File "/Users/admin/airflow/dags/scripts/evaluate_model.py", line 13
    wandb.login '118570a17fac7c4cffe0ad0c784f09cf67222d20'
                ^^^^^^^^^^^^^^^^^^^^^^^^^^^^^^^^^^^^^^^^^^
SyntaxError: invalid syntax
[2025-05-04T23:47:07.605+0300] {processor.py:842} WARNING - No viable dags retrieved from /Users/admin/airflow/dags/etc_pipline.py
[2025-05-04T23:47:07.652+0300] {processor.py:183} INFO - Processing /Users/admin/airflow/dags/etc_pipline.py took 0.730 seconds
[2025-05-04T23:48:36.812+0300] {processor.py:161} INFO - Started process (PID=27536) to work on /Users/admin/airflow/dags/etc_pipline.py
[2025-05-04T23:48:36.813+0300] {processor.py:830} INFO - Processing file /Users/admin/airflow/dags/etc_pipline.py for tasks to queue
[2025-05-04T23:48:36.813+0300] {logging_mixin.py:188} INFO - [2025-05-04T23:48:36.813+0300] {dagbag.py:540} INFO - Filling up the DagBag from /Users/admin/airflow/dags/etc_pipline.py
[2025-05-04T23:48:37.281+0300] {logging_mixin.py:188} INFO - [2025-05-04T23:48:37.281+0300] {utils.py:160} INFO - NumExpr defaulting to 8 threads.
[2025-05-04T23:48:37.565+0300] {logging_mixin.py:188} INFO - [2025-05-04T23:48:37.565+0300] {dagbag.py:350} ERROR - Failed to import: /Users/admin/airflow/dags/etc_pipline.py
Traceback (most recent call last):
  File "/Users/admin/anaconda3/lib/python3.11/site-packages/airflow/models/dagbag.py", line 346, in parse
    loader.exec_module(new_module)
  File "<frozen importlib._bootstrap_external>", line 940, in exec_module
  File "<frozen importlib._bootstrap>", line 241, in _call_with_frames_removed
  File "/Users/admin/airflow/dags/etc_pipline.py", line 8, in <module>
    from scripts import evaluate_model
  File "/Users/admin/airflow/dags/scripts/evaluate_model.py", line 1, in <module>
    from scripts import preprocessing
  File "/Users/admin/airflow/dags/scripts/preprocessing.py", line 168
    if elem == ['Гражданство — Россия']:
    ^^
IndentationError: expected an indented block after 'for' statement on line 167
[2025-05-04T23:48:37.566+0300] {processor.py:842} WARNING - No viable dags retrieved from /Users/admin/airflow/dags/etc_pipline.py
[2025-05-04T23:48:37.612+0300] {processor.py:183} INFO - Processing /Users/admin/airflow/dags/etc_pipline.py took 0.801 seconds
[2025-05-04T23:50:05.794+0300] {processor.py:161} INFO - Started process (PID=27950) to work on /Users/admin/airflow/dags/etc_pipline.py
[2025-05-04T23:50:05.796+0300] {processor.py:830} INFO - Processing file /Users/admin/airflow/dags/etc_pipline.py for tasks to queue
[2025-05-04T23:50:05.796+0300] {logging_mixin.py:188} INFO - [2025-05-04T23:50:05.796+0300] {dagbag.py:540} INFO - Filling up the DagBag from /Users/admin/airflow/dags/etc_pipline.py
[2025-05-04T23:50:06.210+0300] {logging_mixin.py:188} INFO - [2025-05-04T23:50:06.210+0300] {utils.py:160} INFO - NumExpr defaulting to 8 threads.
[2025-05-04T23:50:06.475+0300] {logging_mixin.py:188} INFO - [2025-05-04T23:50:06.474+0300] {dagbag.py:350} ERROR - Failed to import: /Users/admin/airflow/dags/etc_pipline.py
Traceback (most recent call last):
  File "/Users/admin/anaconda3/lib/python3.11/site-packages/airflow/models/dagbag.py", line 346, in parse
    loader.exec_module(new_module)
  File "<frozen importlib._bootstrap_external>", line 940, in exec_module
  File "<frozen importlib._bootstrap>", line 241, in _call_with_frames_removed
  File "/Users/admin/airflow/dags/etc_pipline.py", line 8, in <module>
    from scripts import evaluate_model
  File "/Users/admin/airflow/dags/scripts/evaluate_model.py", line 1, in <module>
    from scripts import preprocessing
  File "/Users/admin/airflow/dags/scripts/preprocessing.py", line 168
    if elem == ['Гражданство — Россия']:
    ^^
IndentationError: expected an indented block after 'for' statement on line 167
[2025-05-04T23:50:06.475+0300] {processor.py:842} WARNING - No viable dags retrieved from /Users/admin/airflow/dags/etc_pipline.py
[2025-05-04T23:50:06.522+0300] {processor.py:183} INFO - Processing /Users/admin/airflow/dags/etc_pipline.py took 0.728 seconds
[2025-05-04T23:51:33.043+0300] {processor.py:161} INFO - Started process (PID=28360) to work on /Users/admin/airflow/dags/etc_pipline.py
[2025-05-04T23:51:33.045+0300] {processor.py:830} INFO - Processing file /Users/admin/airflow/dags/etc_pipline.py for tasks to queue
[2025-05-04T23:51:33.045+0300] {logging_mixin.py:188} INFO - [2025-05-04T23:51:33.045+0300] {dagbag.py:540} INFO - Filling up the DagBag from /Users/admin/airflow/dags/etc_pipline.py
[2025-05-04T23:51:33.482+0300] {logging_mixin.py:188} INFO - [2025-05-04T23:51:33.482+0300] {utils.py:160} INFO - NumExpr defaulting to 8 threads.
[2025-05-04T23:51:44.332+0300] {logging_mixin.py:188} INFO - [2025-05-04T23:51:44.323+0300] {dagbag.py:350} ERROR - Failed to import: /Users/admin/airflow/dags/etc_pipline.py
Traceback (most recent call last):
  File "/Users/admin/anaconda3/lib/python3.11/site-packages/transformers/utils/import_utils.py", line 1863, in _get_module
    return importlib.import_module("." + module_name, self.__name__)
           ^^^^^^^^^^^^^^^^^^^^^^^^^^^^^^^^^^^^^^^^^^^^^^^^^^^^^^^^^
  File "/Users/admin/anaconda3/lib/python3.11/importlib/__init__.py", line 126, in import_module
    return _bootstrap._gcd_import(name[level:], package, level)
           ^^^^^^^^^^^^^^^^^^^^^^^^^^^^^^^^^^^^^^^^^^^^^^^^^^^^
  File "<frozen importlib._bootstrap>", line 1204, in _gcd_import
  File "<frozen importlib._bootstrap>", line 1176, in _find_and_load
  File "<frozen importlib._bootstrap>", line 1126, in _find_and_load_unlocked
  File "<frozen importlib._bootstrap>", line 241, in _call_with_frames_removed
  File "<frozen importlib._bootstrap>", line 1204, in _gcd_import
  File "<frozen importlib._bootstrap>", line 1176, in _find_and_load
  File "<frozen importlib._bootstrap>", line 1147, in _find_and_load_unlocked
  File "<frozen importlib._bootstrap>", line 690, in _load_unlocked
  File "<frozen importlib._bootstrap_external>", line 940, in exec_module
  File "<frozen importlib._bootstrap>", line 241, in _call_with_frames_removed
  File "/Users/admin/anaconda3/lib/python3.11/site-packages/transformers/data/__init__.py", line 29, in <module>
    from .processors import (
  File "/Users/admin/anaconda3/lib/python3.11/site-packages/transformers/data/processors/__init__.py", line 15, in <module>
    from .glue import glue_convert_examples_to_features, glue_output_modes, glue_processors, glue_tasks_num_labels
  File "/Users/admin/anaconda3/lib/python3.11/site-packages/transformers/data/processors/glue.py", line 79, in <module>
    examples: tf.data.Dataset,
              ^^^^^^^
AttributeError: module 'tensorflow' has no attribute 'data'

The above exception was the direct cause of the following exception:

Traceback (most recent call last):
  File "/Users/admin/anaconda3/lib/python3.11/site-packages/transformers/utils/import_utils.py", line 1863, in _get_module
    return importlib.import_module("." + module_name, self.__name__)
           ^^^^^^^^^^^^^^^^^^^^^^^^^^^^^^^^^^^^^^^^^^^^^^^^^^^^^^^^^
  File "/Users/admin/anaconda3/lib/python3.11/importlib/__init__.py", line 126, in import_module
    return _bootstrap._gcd_import(name[level:], package, level)
           ^^^^^^^^^^^^^^^^^^^^^^^^^^^^^^^^^^^^^^^^^^^^^^^^^^^^
  File "<frozen importlib._bootstrap>", line 1204, in _gcd_import
  File "<frozen importlib._bootstrap>", line 1176, in _find_and_load
  File "<frozen importlib._bootstrap>", line 1147, in _find_and_load_unlocked
  File "<frozen importlib._bootstrap>", line 690, in _load_unlocked
  File "<frozen importlib._bootstrap_external>", line 940, in exec_module
  File "<frozen importlib._bootstrap>", line 241, in _call_with_frames_removed
  File "/Users/admin/anaconda3/lib/python3.11/site-packages/transformers/modeling_tf_utils.py", line 37, in <module>
    from . import DataCollatorWithPadding, DefaultDataCollator
  File "<frozen importlib._bootstrap>", line 1229, in _handle_fromlist
  File "/Users/admin/anaconda3/lib/python3.11/site-packages/transformers/utils/import_utils.py", line 1851, in __getattr__
    module = self._get_module(self._class_to_module[name])
             ^^^^^^^^^^^^^^^^^^^^^^^^^^^^^^^^^^^^^^^^^^^^^
  File "/Users/admin/anaconda3/lib/python3.11/site-packages/transformers/utils/import_utils.py", line 1865, in _get_module
    raise RuntimeError(
RuntimeError: Failed to import transformers.data.data_collator because of the following error (look up to see its traceback):
module 'tensorflow' has no attribute 'data'

The above exception was the direct cause of the following exception:

Traceback (most recent call last):
  File "/Users/admin/anaconda3/lib/python3.11/site-packages/transformers/utils/import_utils.py", line 1863, in _get_module
    return importlib.import_module("." + module_name, self.__name__)
           ^^^^^^^^^^^^^^^^^^^^^^^^^^^^^^^^^^^^^^^^^^^^^^^^^^^^^^^^^
  File "/Users/admin/anaconda3/lib/python3.11/importlib/__init__.py", line 126, in import_module
    return _bootstrap._gcd_import(name[level:], package, level)
           ^^^^^^^^^^^^^^^^^^^^^^^^^^^^^^^^^^^^^^^^^^^^^^^^^^^^
  File "<frozen importlib._bootstrap>", line 1204, in _gcd_import
  File "<frozen importlib._bootstrap>", line 1176, in _find_and_load
  File "<frozen importlib._bootstrap>", line 1147, in _find_and_load_unlocked
  File "<frozen importlib._bootstrap>", line 690, in _load_unlocked
  File "<frozen importlib._bootstrap_external>", line 940, in exec_module
  File "<frozen importlib._bootstrap>", line 241, in _call_with_frames_removed
  File "/Users/admin/anaconda3/lib/python3.11/site-packages/transformers/integrations/integration_utils.py", line 36, in <module>
    from .. import PreTrainedModel, TFPreTrainedModel
  File "<frozen importlib._bootstrap>", line 1229, in _handle_fromlist
  File "/Users/admin/anaconda3/lib/python3.11/site-packages/transformers/utils/import_utils.py", line 1851, in __getattr__
    module = self._get_module(self._class_to_module[name])
             ^^^^^^^^^^^^^^^^^^^^^^^^^^^^^^^^^^^^^^^^^^^^^
  File "/Users/admin/anaconda3/lib/python3.11/site-packages/transformers/utils/import_utils.py", line 1865, in _get_module
    raise RuntimeError(
RuntimeError: Failed to import transformers.modeling_tf_utils because of the following error (look up to see its traceback):
Failed to import transformers.data.data_collator because of the following error (look up to see its traceback):
module 'tensorflow' has no attribute 'data'

The above exception was the direct cause of the following exception:

Traceback (most recent call last):
  File "/Users/admin/anaconda3/lib/python3.11/site-packages/airflow/models/dagbag.py", line 346, in parse
    loader.exec_module(new_module)
  File "<frozen importlib._bootstrap_external>", line 940, in exec_module
  File "<frozen importlib._bootstrap>", line 241, in _call_with_frames_removed
  File "/Users/admin/airflow/dags/etc_pipline.py", line 8, in <module>
    from scripts import evaluate_model
  File "/Users/admin/airflow/dags/scripts/evaluate_model.py", line 2, in <module>
    from sentence_transformers import SentenceTransformer
  File "/Users/admin/anaconda3/lib/python3.11/site-packages/sentence_transformers/__init__.py", line 14, in <module>
    from sentence_transformers.cross_encoder.CrossEncoder import CrossEncoder
  File "/Users/admin/anaconda3/lib/python3.11/site-packages/sentence_transformers/cross_encoder/__init__.py", line 3, in <module>
    from .CrossEncoder import CrossEncoder
  File "/Users/admin/anaconda3/lib/python3.11/site-packages/sentence_transformers/cross_encoder/CrossEncoder.py", line 18, in <module>
    from sentence_transformers.evaluation.SentenceEvaluator import SentenceEvaluator
  File "/Users/admin/anaconda3/lib/python3.11/site-packages/sentence_transformers/evaluation/__init__.py", line 9, in <module>
    from .NanoBEIREvaluator import NanoBEIREvaluator
  File "/Users/admin/anaconda3/lib/python3.11/site-packages/sentence_transformers/evaluation/NanoBEIREvaluator.py", line 11, in <module>
    from sentence_transformers import SentenceTransformer
  File "/Users/admin/anaconda3/lib/python3.11/site-packages/sentence_transformers/SentenceTransformer.py", line 33, in <module>
    from sentence_transformers.model_card import SentenceTransformerModelCardData, generate_model_card
  File "/Users/admin/anaconda3/lib/python3.11/site-packages/sentence_transformers/model_card.py", line 25, in <module>
    from transformers.integrations import CodeCarbonCallback
  File "<frozen importlib._bootstrap>", line 1229, in _handle_fromlist
  File "/Users/admin/anaconda3/lib/python3.11/site-packages/transformers/utils/import_utils.py", line 1851, in __getattr__
    module = self._get_module(self._class_to_module[name])
             ^^^^^^^^^^^^^^^^^^^^^^^^^^^^^^^^^^^^^^^^^^^^^
  File "/Users/admin/anaconda3/lib/python3.11/site-packages/transformers/utils/import_utils.py", line 1865, in _get_module
    raise RuntimeError(
RuntimeError: Failed to import transformers.integrations.integration_utils because of the following error (look up to see its traceback):
Failed to import transformers.modeling_tf_utils because of the following error (look up to see its traceback):
Failed to import transformers.data.data_collator because of the following error (look up to see its traceback):
module 'tensorflow' has no attribute 'data'
[2025-05-04T23:51:44.335+0300] {processor.py:842} WARNING - No viable dags retrieved from /Users/admin/airflow/dags/etc_pipline.py
[2025-05-04T23:51:44.404+0300] {processor.py:183} INFO - Processing /Users/admin/airflow/dags/etc_pipline.py took 11.361 seconds
[2025-05-04T23:53:14.772+0300] {processor.py:161} INFO - Started process (PID=28834) to work on /Users/admin/airflow/dags/etc_pipline.py
[2025-05-04T23:53:14.772+0300] {processor.py:830} INFO - Processing file /Users/admin/airflow/dags/etc_pipline.py for tasks to queue
[2025-05-04T23:53:14.773+0300] {logging_mixin.py:188} INFO - [2025-05-04T23:53:14.772+0300] {dagbag.py:540} INFO - Filling up the DagBag from /Users/admin/airflow/dags/etc_pipline.py
[2025-05-04T23:53:15.075+0300] {logging_mixin.py:188} INFO - [2025-05-04T23:53:15.075+0300] {utils.py:160} INFO - NumExpr defaulting to 8 threads.
[2025-05-04T23:53:18.176+0300] {logging_mixin.py:188} INFO - [2025-05-04T23:53:18.169+0300] {dagbag.py:350} ERROR - Failed to import: /Users/admin/airflow/dags/etc_pipline.py
Traceback (most recent call last):
  File "/Users/admin/anaconda3/lib/python3.11/site-packages/transformers/utils/import_utils.py", line 1863, in _get_module
    return importlib.import_module("." + module_name, self.__name__)
           ^^^^^^^^^^^^^^^^^^^^^^^^^^^^^^^^^^^^^^^^^^^^^^^^^^^^^^^^^
  File "/Users/admin/anaconda3/lib/python3.11/importlib/__init__.py", line 126, in import_module
    return _bootstrap._gcd_import(name[level:], package, level)
           ^^^^^^^^^^^^^^^^^^^^^^^^^^^^^^^^^^^^^^^^^^^^^^^^^^^^
  File "<frozen importlib._bootstrap>", line 1204, in _gcd_import
  File "<frozen importlib._bootstrap>", line 1176, in _find_and_load
  File "<frozen importlib._bootstrap>", line 1126, in _find_and_load_unlocked
  File "<frozen importlib._bootstrap>", line 241, in _call_with_frames_removed
  File "<frozen importlib._bootstrap>", line 1204, in _gcd_import
  File "<frozen importlib._bootstrap>", line 1176, in _find_and_load
  File "<frozen importlib._bootstrap>", line 1147, in _find_and_load_unlocked
  File "<frozen importlib._bootstrap>", line 690, in _load_unlocked
  File "<frozen importlib._bootstrap_external>", line 940, in exec_module
  File "<frozen importlib._bootstrap>", line 241, in _call_with_frames_removed
  File "/Users/admin/anaconda3/lib/python3.11/site-packages/transformers/data/__init__.py", line 29, in <module>
    from .processors import (
  File "/Users/admin/anaconda3/lib/python3.11/site-packages/transformers/data/processors/__init__.py", line 15, in <module>
    from .glue import glue_convert_examples_to_features, glue_output_modes, glue_processors, glue_tasks_num_labels
  File "/Users/admin/anaconda3/lib/python3.11/site-packages/transformers/data/processors/glue.py", line 79, in <module>
    examples: tf.data.Dataset,
              ^^^^^^^
AttributeError: module 'tensorflow' has no attribute 'data'

The above exception was the direct cause of the following exception:

Traceback (most recent call last):
  File "/Users/admin/anaconda3/lib/python3.11/site-packages/transformers/utils/import_utils.py", line 1863, in _get_module
    return importlib.import_module("." + module_name, self.__name__)
           ^^^^^^^^^^^^^^^^^^^^^^^^^^^^^^^^^^^^^^^^^^^^^^^^^^^^^^^^^
  File "/Users/admin/anaconda3/lib/python3.11/importlib/__init__.py", line 126, in import_module
    return _bootstrap._gcd_import(name[level:], package, level)
           ^^^^^^^^^^^^^^^^^^^^^^^^^^^^^^^^^^^^^^^^^^^^^^^^^^^^
  File "<frozen importlib._bootstrap>", line 1204, in _gcd_import
  File "<frozen importlib._bootstrap>", line 1176, in _find_and_load
  File "<frozen importlib._bootstrap>", line 1147, in _find_and_load_unlocked
  File "<frozen importlib._bootstrap>", line 690, in _load_unlocked
  File "<frozen importlib._bootstrap_external>", line 940, in exec_module
  File "<frozen importlib._bootstrap>", line 241, in _call_with_frames_removed
  File "/Users/admin/anaconda3/lib/python3.11/site-packages/transformers/modeling_tf_utils.py", line 37, in <module>
    from . import DataCollatorWithPadding, DefaultDataCollator
  File "<frozen importlib._bootstrap>", line 1229, in _handle_fromlist
  File "/Users/admin/anaconda3/lib/python3.11/site-packages/transformers/utils/import_utils.py", line 1851, in __getattr__
    module = self._get_module(self._class_to_module[name])
             ^^^^^^^^^^^^^^^^^^^^^^^^^^^^^^^^^^^^^^^^^^^^^
  File "/Users/admin/anaconda3/lib/python3.11/site-packages/transformers/utils/import_utils.py", line 1865, in _get_module
    raise RuntimeError(
RuntimeError: Failed to import transformers.data.data_collator because of the following error (look up to see its traceback):
module 'tensorflow' has no attribute 'data'

The above exception was the direct cause of the following exception:

Traceback (most recent call last):
  File "/Users/admin/anaconda3/lib/python3.11/site-packages/transformers/utils/import_utils.py", line 1863, in _get_module
    return importlib.import_module("." + module_name, self.__name__)
           ^^^^^^^^^^^^^^^^^^^^^^^^^^^^^^^^^^^^^^^^^^^^^^^^^^^^^^^^^
  File "/Users/admin/anaconda3/lib/python3.11/importlib/__init__.py", line 126, in import_module
    return _bootstrap._gcd_import(name[level:], package, level)
           ^^^^^^^^^^^^^^^^^^^^^^^^^^^^^^^^^^^^^^^^^^^^^^^^^^^^
  File "<frozen importlib._bootstrap>", line 1204, in _gcd_import
  File "<frozen importlib._bootstrap>", line 1176, in _find_and_load
  File "<frozen importlib._bootstrap>", line 1147, in _find_and_load_unlocked
  File "<frozen importlib._bootstrap>", line 690, in _load_unlocked
  File "<frozen importlib._bootstrap_external>", line 940, in exec_module
  File "<frozen importlib._bootstrap>", line 241, in _call_with_frames_removed
  File "/Users/admin/anaconda3/lib/python3.11/site-packages/transformers/integrations/integration_utils.py", line 36, in <module>
    from .. import PreTrainedModel, TFPreTrainedModel
  File "<frozen importlib._bootstrap>", line 1229, in _handle_fromlist
  File "/Users/admin/anaconda3/lib/python3.11/site-packages/transformers/utils/import_utils.py", line 1851, in __getattr__
    module = self._get_module(self._class_to_module[name])
             ^^^^^^^^^^^^^^^^^^^^^^^^^^^^^^^^^^^^^^^^^^^^^
  File "/Users/admin/anaconda3/lib/python3.11/site-packages/transformers/utils/import_utils.py", line 1865, in _get_module
    raise RuntimeError(
RuntimeError: Failed to import transformers.modeling_tf_utils because of the following error (look up to see its traceback):
Failed to import transformers.data.data_collator because of the following error (look up to see its traceback):
module 'tensorflow' has no attribute 'data'

The above exception was the direct cause of the following exception:

Traceback (most recent call last):
  File "/Users/admin/anaconda3/lib/python3.11/site-packages/airflow/models/dagbag.py", line 346, in parse
    loader.exec_module(new_module)
  File "<frozen importlib._bootstrap_external>", line 940, in exec_module
  File "<frozen importlib._bootstrap>", line 241, in _call_with_frames_removed
  File "/Users/admin/airflow/dags/etc_pipline.py", line 8, in <module>
    from scripts import evaluate_model
  File "/Users/admin/airflow/dags/scripts/evaluate_model.py", line 2, in <module>
    from sentence_transformers import SentenceTransformer
  File "/Users/admin/anaconda3/lib/python3.11/site-packages/sentence_transformers/__init__.py", line 14, in <module>
    from sentence_transformers.cross_encoder.CrossEncoder import CrossEncoder
  File "/Users/admin/anaconda3/lib/python3.11/site-packages/sentence_transformers/cross_encoder/__init__.py", line 3, in <module>
    from .CrossEncoder import CrossEncoder
  File "/Users/admin/anaconda3/lib/python3.11/site-packages/sentence_transformers/cross_encoder/CrossEncoder.py", line 18, in <module>
    from sentence_transformers.evaluation.SentenceEvaluator import SentenceEvaluator
  File "/Users/admin/anaconda3/lib/python3.11/site-packages/sentence_transformers/evaluation/__init__.py", line 9, in <module>
    from .NanoBEIREvaluator import NanoBEIREvaluator
  File "/Users/admin/anaconda3/lib/python3.11/site-packages/sentence_transformers/evaluation/NanoBEIREvaluator.py", line 11, in <module>
    from sentence_transformers import SentenceTransformer
  File "/Users/admin/anaconda3/lib/python3.11/site-packages/sentence_transformers/SentenceTransformer.py", line 33, in <module>
    from sentence_transformers.model_card import SentenceTransformerModelCardData, generate_model_card
  File "/Users/admin/anaconda3/lib/python3.11/site-packages/sentence_transformers/model_card.py", line 25, in <module>
    from transformers.integrations import CodeCarbonCallback
  File "<frozen importlib._bootstrap>", line 1229, in _handle_fromlist
  File "/Users/admin/anaconda3/lib/python3.11/site-packages/transformers/utils/import_utils.py", line 1851, in __getattr__
    module = self._get_module(self._class_to_module[name])
             ^^^^^^^^^^^^^^^^^^^^^^^^^^^^^^^^^^^^^^^^^^^^^
  File "/Users/admin/anaconda3/lib/python3.11/site-packages/transformers/utils/import_utils.py", line 1865, in _get_module
    raise RuntimeError(
RuntimeError: Failed to import transformers.integrations.integration_utils because of the following error (look up to see its traceback):
Failed to import transformers.modeling_tf_utils because of the following error (look up to see its traceback):
Failed to import transformers.data.data_collator because of the following error (look up to see its traceback):
module 'tensorflow' has no attribute 'data'
[2025-05-04T23:53:18.178+0300] {processor.py:842} WARNING - No viable dags retrieved from /Users/admin/airflow/dags/etc_pipline.py
[2025-05-04T23:53:18.229+0300] {processor.py:183} INFO - Processing /Users/admin/airflow/dags/etc_pipline.py took 3.459 seconds
[2025-05-04T23:59:11.603+0300] {processor.py:161} INFO - Started process (PID=29302) to work on /Users/admin/airflow/dags/etc_pipline.py
[2025-05-04T23:59:11.604+0300] {processor.py:830} INFO - Processing file /Users/admin/airflow/dags/etc_pipline.py for tasks to queue
[2025-05-04T23:59:11.604+0300] {logging_mixin.py:188} INFO - [2025-05-04T23:59:11.604+0300] {dagbag.py:540} INFO - Filling up the DagBag from /Users/admin/airflow/dags/etc_pipline.py
[2025-05-04T23:59:11.830+0300] {logging_mixin.py:188} INFO - [2025-05-04T23:59:11.830+0300] {utils.py:160} INFO - NumExpr defaulting to 8 threads.
[2025-05-04T23:59:15.589+0300] {logging_mixin.py:188} INFO - [2025-05-04T23:59:15.582+0300] {dagbag.py:350} ERROR - Failed to import: /Users/admin/airflow/dags/etc_pipline.py
Traceback (most recent call last):
  File "/Users/admin/anaconda3/lib/python3.11/site-packages/transformers/utils/import_utils.py", line 1863, in _get_module
    return importlib.import_module("." + module_name, self.__name__)
           ^^^^^^^^^^^^^^^^^^^^^^^^^^^^^^^^^^^^^^^^^^^^^^^^^^^^^^^^^
  File "/Users/admin/anaconda3/lib/python3.11/importlib/__init__.py", line 126, in import_module
    return _bootstrap._gcd_import(name[level:], package, level)
           ^^^^^^^^^^^^^^^^^^^^^^^^^^^^^^^^^^^^^^^^^^^^^^^^^^^^
  File "<frozen importlib._bootstrap>", line 1204, in _gcd_import
  File "<frozen importlib._bootstrap>", line 1176, in _find_and_load
  File "<frozen importlib._bootstrap>", line 1126, in _find_and_load_unlocked
  File "<frozen importlib._bootstrap>", line 241, in _call_with_frames_removed
  File "<frozen importlib._bootstrap>", line 1204, in _gcd_import
  File "<frozen importlib._bootstrap>", line 1176, in _find_and_load
  File "<frozen importlib._bootstrap>", line 1147, in _find_and_load_unlocked
  File "<frozen importlib._bootstrap>", line 690, in _load_unlocked
  File "<frozen importlib._bootstrap_external>", line 940, in exec_module
  File "<frozen importlib._bootstrap>", line 241, in _call_with_frames_removed
  File "/Users/admin/anaconda3/lib/python3.11/site-packages/transformers/data/__init__.py", line 29, in <module>
    from .processors import (
  File "/Users/admin/anaconda3/lib/python3.11/site-packages/transformers/data/processors/__init__.py", line 15, in <module>
    from .glue import glue_convert_examples_to_features, glue_output_modes, glue_processors, glue_tasks_num_labels
  File "/Users/admin/anaconda3/lib/python3.11/site-packages/transformers/data/processors/glue.py", line 79, in <module>
    examples: tf.data.Dataset,
              ^^^^^^^
AttributeError: module 'tensorflow' has no attribute 'data'

The above exception was the direct cause of the following exception:

Traceback (most recent call last):
  File "/Users/admin/anaconda3/lib/python3.11/site-packages/transformers/utils/import_utils.py", line 1863, in _get_module
    return importlib.import_module("." + module_name, self.__name__)
           ^^^^^^^^^^^^^^^^^^^^^^^^^^^^^^^^^^^^^^^^^^^^^^^^^^^^^^^^^
  File "/Users/admin/anaconda3/lib/python3.11/importlib/__init__.py", line 126, in import_module
    return _bootstrap._gcd_import(name[level:], package, level)
           ^^^^^^^^^^^^^^^^^^^^^^^^^^^^^^^^^^^^^^^^^^^^^^^^^^^^
  File "<frozen importlib._bootstrap>", line 1204, in _gcd_import
  File "<frozen importlib._bootstrap>", line 1176, in _find_and_load
  File "<frozen importlib._bootstrap>", line 1147, in _find_and_load_unlocked
  File "<frozen importlib._bootstrap>", line 690, in _load_unlocked
  File "<frozen importlib._bootstrap_external>", line 940, in exec_module
  File "<frozen importlib._bootstrap>", line 241, in _call_with_frames_removed
  File "/Users/admin/anaconda3/lib/python3.11/site-packages/transformers/modeling_tf_utils.py", line 37, in <module>
    from . import DataCollatorWithPadding, DefaultDataCollator
  File "<frozen importlib._bootstrap>", line 1229, in _handle_fromlist
  File "/Users/admin/anaconda3/lib/python3.11/site-packages/transformers/utils/import_utils.py", line 1851, in __getattr__
    module = self._get_module(self._class_to_module[name])
             ^^^^^^^^^^^^^^^^^^^^^^^^^^^^^^^^^^^^^^^^^^^^^
  File "/Users/admin/anaconda3/lib/python3.11/site-packages/transformers/utils/import_utils.py", line 1865, in _get_module
    raise RuntimeError(
RuntimeError: Failed to import transformers.data.data_collator because of the following error (look up to see its traceback):
module 'tensorflow' has no attribute 'data'

The above exception was the direct cause of the following exception:

Traceback (most recent call last):
  File "/Users/admin/anaconda3/lib/python3.11/site-packages/transformers/utils/import_utils.py", line 1863, in _get_module
    return importlib.import_module("." + module_name, self.__name__)
           ^^^^^^^^^^^^^^^^^^^^^^^^^^^^^^^^^^^^^^^^^^^^^^^^^^^^^^^^^
  File "/Users/admin/anaconda3/lib/python3.11/importlib/__init__.py", line 126, in import_module
    return _bootstrap._gcd_import(name[level:], package, level)
           ^^^^^^^^^^^^^^^^^^^^^^^^^^^^^^^^^^^^^^^^^^^^^^^^^^^^
  File "<frozen importlib._bootstrap>", line 1204, in _gcd_import
  File "<frozen importlib._bootstrap>", line 1176, in _find_and_load
  File "<frozen importlib._bootstrap>", line 1147, in _find_and_load_unlocked
  File "<frozen importlib._bootstrap>", line 690, in _load_unlocked
  File "<frozen importlib._bootstrap_external>", line 940, in exec_module
  File "<frozen importlib._bootstrap>", line 241, in _call_with_frames_removed
  File "/Users/admin/anaconda3/lib/python3.11/site-packages/transformers/integrations/integration_utils.py", line 36, in <module>
    from .. import PreTrainedModel, TFPreTrainedModel
  File "<frozen importlib._bootstrap>", line 1229, in _handle_fromlist
  File "/Users/admin/anaconda3/lib/python3.11/site-packages/transformers/utils/import_utils.py", line 1851, in __getattr__
    module = self._get_module(self._class_to_module[name])
             ^^^^^^^^^^^^^^^^^^^^^^^^^^^^^^^^^^^^^^^^^^^^^
  File "/Users/admin/anaconda3/lib/python3.11/site-packages/transformers/utils/import_utils.py", line 1865, in _get_module
    raise RuntimeError(
RuntimeError: Failed to import transformers.modeling_tf_utils because of the following error (look up to see its traceback):
Failed to import transformers.data.data_collator because of the following error (look up to see its traceback):
module 'tensorflow' has no attribute 'data'

The above exception was the direct cause of the following exception:

Traceback (most recent call last):
  File "/Users/admin/anaconda3/lib/python3.11/site-packages/airflow/models/dagbag.py", line 346, in parse
    loader.exec_module(new_module)
  File "<frozen importlib._bootstrap_external>", line 940, in exec_module
  File "<frozen importlib._bootstrap>", line 241, in _call_with_frames_removed
  File "/Users/admin/airflow/dags/etc_pipline.py", line 8, in <module>
    from scripts import evaluate_model
  File "/Users/admin/airflow/dags/scripts/evaluate_model.py", line 2, in <module>
    from sentence_transformers import SentenceTransformer
  File "/Users/admin/anaconda3/lib/python3.11/site-packages/sentence_transformers/__init__.py", line 14, in <module>
    from sentence_transformers.cross_encoder.CrossEncoder import CrossEncoder
  File "/Users/admin/anaconda3/lib/python3.11/site-packages/sentence_transformers/cross_encoder/__init__.py", line 3, in <module>
    from .CrossEncoder import CrossEncoder
  File "/Users/admin/anaconda3/lib/python3.11/site-packages/sentence_transformers/cross_encoder/CrossEncoder.py", line 18, in <module>
    from sentence_transformers.evaluation.SentenceEvaluator import SentenceEvaluator
  File "/Users/admin/anaconda3/lib/python3.11/site-packages/sentence_transformers/evaluation/__init__.py", line 9, in <module>
    from .NanoBEIREvaluator import NanoBEIREvaluator
  File "/Users/admin/anaconda3/lib/python3.11/site-packages/sentence_transformers/evaluation/NanoBEIREvaluator.py", line 11, in <module>
    from sentence_transformers import SentenceTransformer
  File "/Users/admin/anaconda3/lib/python3.11/site-packages/sentence_transformers/SentenceTransformer.py", line 33, in <module>
    from sentence_transformers.model_card import SentenceTransformerModelCardData, generate_model_card
  File "/Users/admin/anaconda3/lib/python3.11/site-packages/sentence_transformers/model_card.py", line 25, in <module>
    from transformers.integrations import CodeCarbonCallback
  File "<frozen importlib._bootstrap>", line 1229, in _handle_fromlist
  File "/Users/admin/anaconda3/lib/python3.11/site-packages/transformers/utils/import_utils.py", line 1851, in __getattr__
    module = self._get_module(self._class_to_module[name])
             ^^^^^^^^^^^^^^^^^^^^^^^^^^^^^^^^^^^^^^^^^^^^^
  File "/Users/admin/anaconda3/lib/python3.11/site-packages/transformers/utils/import_utils.py", line 1865, in _get_module
    raise RuntimeError(
RuntimeError: Failed to import transformers.integrations.integration_utils because of the following error (look up to see its traceback):
Failed to import transformers.modeling_tf_utils because of the following error (look up to see its traceback):
Failed to import transformers.data.data_collator because of the following error (look up to see its traceback):
module 'tensorflow' has no attribute 'data'
[2025-05-04T23:59:15.591+0300] {processor.py:842} WARNING - No viable dags retrieved from /Users/admin/airflow/dags/etc_pipline.py
[2025-05-04T23:59:15.639+0300] {processor.py:183} INFO - Processing /Users/admin/airflow/dags/etc_pipline.py took 4.038 seconds
